Workbook

Sheet Cover
B2: RMTI–HCC · Triage & Evidence-Grading Calculator (v2.3.0)
B3: Risk Mechanism Theory Index, adapted for hepatocellular-carcinoma surveillance — a single, auditable score from likelihood, exposure, vulnerability and resilience.
B5: The model at a glance
B6: Core score (Eq. 1–2) | C6: R = IR × (1−ρ) = L · E · V · (1−ρ) — residual risk, bounded [0,1]
B7: Multi-hazard, multi-category (Eq. 3/5) | C7: R = Σₕ Σ_c w_c · L_h · E_hc · V_hc · (1−ρ_hc) — category weights sum to 1. Implemented in RMTI-Py 2.3.0 (shared core); this workbook implements the single-insult form above.
B8: Exposure from N (Eq. 4) | C8: E-log = [log₁₀(N) − log₁₀(Nmin)] / [log₁₀(Nmax) − log₁₀(Nmin)], Nmin = 100, Nmax = 5,000,000 (HCC bounds, same as RMTI-Py). Advisory helper only.
B9: Severity layer (Eq. 5–6) | C9: EAL = L · C · (1−ρ) — carries consequence through, where a probability-only metric would suppress it
B10: Per-capita equity (Eq. 7) | C10: Rate = EAL ÷ N × 1,000,000 — events-equivalent per 1,000,000 at-risk patients (RMTI-Py equity_per_1M)
B11: Fixed tiers | C11: 1 Low R<0.05 · 2 Moderate 0.05–0.15 · 3 High 0.15–0.35 · 4 Severe 0.35–0.60 · 5 Critical R≥0.60
B13: What’s inside
B14: • How to Use — step-by-step input guide, plus the within-tier EAL walk-through (Patients A & B).
B15: • RMTI Calculator — all 12 worked cohorts from the paper (Tables 2 & 3) and Patients A & B, auto-calculating; add your own below.
B16: • ALBI → Vulnerability — compute V from measured albumin/bilirubin (patient-level) or a grade distribution (cohort-level, reproduces Table 1a).
B17: • Reference — bounds, fixed tiers with HCC surveillance posture, consequence/BCLC ladder, resilience ladder, Table 4 indicator backbone.
B18: • Data sources — what each number is anchored to, and what remains a pre-specified working calibration.
B19: • Trajectory — experimental time-indexed V(t) and ρ(t) per surveillance cycle, with two synthetic examples (not validated).
B20: What changed from the v1 workbook (aligned to RMTI-Py 2.3.0; items below date from v2.1.0)
B21: Item | C21: Change
B22: Wording | C22: Posture text is now in oncology (surveillance-programme) vocabulary; Tier 1 and Tier 2 are worded differently.
B23: Population bounds | C23: Nmin/Nmax 10 / 650,000 → 100 / 5,000,000 (the Python HCC bounds). Only the advisory E-log column moves; R, tier and EAL are unaffected.
B24: Per-capita unit | C24: EAL ÷ N × 100,000 → EAL ÷ N × 1,000,000 (the Python unit). Numerically 10× the old values.
B25: ALBI cohort counts | C25: HCC cohort grade counts corrected from 9/19/1 to 10/18/1 (V = 0.522, matching Table 1a and the Python test suite); v1 gave 0.531 and explained the gap as rounding.
B26: Ranking and rounding | C26: EAL is rounded to 3 decimals and Priority ranks on it (as in RMTI-Py). Tier, Δ risk and IEI unchanged in definition.
B27: New columns | C27: Improvement efficiency (IEI), E-log helper and both posture columns are now on the calculator sheet.
B29: Built from Marolla, “The Risk Mechanism Theory Index (RMTI) as a Triage and Evidence-Grading Layer for Hepatocellular-Carcinoma Surveillance” (manuscript). Equations, anchors and cohort data are reproduced from the paper and the RMTI-Py reference implementation (version 2.3.0). Licensed under the Apache License, Version 2.0 (see LICENSE and NOTICE in the repository). Copyright 2026 Cesar Marolla (ORCID 0000-0001-8498-7380). Provided "as is", without warranty. Decision-support illustration; not validated for clinical use (see Limitations).

Sheet How to Use
B2: How to use the RMTI–HCC Calculator
B3: Type into the warm-shaded (blue-text) cells only. Everything else recalculates automatically.
B5: Step 1 — Enter the inputs (warm cells)
B6: L · Likelihood | C6: Annualized HCC probability, supplied by a validated score (aMAP, THRI, hccrisk.com) — not re-derived here, 0–1.
B7: E · Exposure | C7: Share of the at-risk population in the active surveillance footprint, 0–1. Programme-level rubric, or copy the E-log helper column.
B8: V · Vulnerability | C8: Liver-reserve sensitivity to a missed diagnosis, from ALBI grade (see the ALBI → Vulnerability sheet), 0–1.
B9: ρ now / ρ after | C9: Resilience — fraction of inherent risk the surveillance programme absorbs, before/after an improvement package, 0–1. Enters as (1−ρ).
B10: C · Consequence (1–5) | C10: Severity if a tumour is missed: 1 Insignificant → 5 Severe, anchored to BCLC stage at detection. Maps to 0–1 for EAL.
B11: N · At-risk patients | C11: At-risk population or registry size. Drives the per-capita column and the advisory E-log column only — never R, tier or EAL directly.
B13: Step 2 — Read the results (auto-calculated)
B14: Inherent risk (IR) | C14: L · E · V — risk before resilience is applied (Eq. 1).
B15: R now / R after | C15: IR × (1−ρ) — the residual decision score, bounded 0–1 (Eq. 2).
B16: Tier and posture | C16: Maps R to the fixed 1–5 band — same thresholds for every patient, every run — and reports the surveillance posture for that tier.
B17: Δ risk | C17: Percentage cut in R from the surveillance-improvement package.
B18: EAL now / after | C18: L · C · (1−ρ) — expected-loss index that carries severity through (Eq. 6).
B19: Per-capita rate | C19: EAL ÷ N, per 1,000,000 at-risk patients — the equity lens (Eq. 7).
B20: Priority (in tier) | C20: Rank within the same tier by EAL — the case with more to lose in consequence outranks one with only marginally higher R.
B21: IEI | C21: Improvement efficiency = Δ risk ÷ (1 − ρ after).
B23: Worked walk-through — within-tier EAL example
B24: Patient A — post-SVR HCV, preserved reserve: L=0.30, E=0.60, V=0.50, ρ=0.20, C=2 (Minor, 0.30)
B25: R = 0.30 × 0.60 × 0.50 × 0.80 = 0.072 (2 Moderate) → EAL = 0.30 × 0.30 × 0.80 = 0.072
B26: Patient B — alcohol-related, marginal reserve: L=0.25, E=0.60, V=0.55, ρ=0.20, C=5 (Severe, 1.00)
B27: R = 0.25 × 0.60 × 0.55 × 0.80 = 0.066 (2 Moderate) → EAL = 0.25 × 1.00 × 0.80 = 0.200
B28: On R alone, A outranks B. But EAL reverses the within-tier order — B’s tumour, if missed, presents advanced and fatal; A’s presents early and curable.
B29: This is exactly the Priority (in tier) column in the RMTI Calculator sheet: same tier, ranked by EAL.
B31: Built from Marolla, “The Risk Mechanism Theory Index (RMTI) as a Triage and Evidence-Grading Layer for Hepatocellular-Carcinoma Surveillance” (manuscript). Equations, anchors and cohort data are reproduced from the paper and the RMTI-Py reference implementation (version 2.3.0). Licensed under the Apache License, Version 2.0 (see LICENSE and NOTICE in the repository). Copyright 2026 Cesar Marolla (ORCID 0000-0001-8498-7380). Provided "as is", without warranty. Decision-support illustration; not validated for clinical use (see Limitations).

Sheet RMTI Calculator
A1: RMTI–HCC Calculator v2.3.0 — cohort and patient triage
A2: Inputs are the warm-shaded cells with blue text; grey columns auto-calculate. Rows 5–10 reproduce Table 2 (published cohorts); rows 11–16 reproduce Table 3 (Pearl-protocol aetiologies); rows 17–18 are the Patient A/B within-tier EAL walk-through. Add your own patients or cohorts from row 19 down (formulas are pre-filled to row 56).
A4: Cohort / patient | B4: Source | C4: Aetiology (annual incidence) | D4: N (at-risk patients) | E4: L | F4: E | G4: V | H4: ρ now | I4: ρ after | J4: C (1–5) | K4: C (0–1) | L4: Inherent L·E·V | M4: R now | N4: Tier now | O4: R after | P4: Tier after | Q4: Δ risk | R4: EAL now | S4: EAL after | T4: Per-capita now (EAL per 1,000,000) | U4: Priority (in tier) | V4: Improvement efficiency (IEI) | W4: E-log (advisory) | X4: Surveillance posture — now | Y4: Surveillance posture — after
A5: Untreated HBV | B5: Table 2 | C5: ~12.8%/yr (historical) | D5: 100000 | E5: 0.9 | F5: 0.7 | G5: 0.55 | H5: 0.1 | I5: 0.45 | J5: 5 | K5: =IF($J5="","",INDEX(Reference!$C$20:$C$24,$J5)) -> 1 | L5: =IF(OR($E5="",$F5="",$G5=""),"",ROUND($E5*$F5*$G5,12)) -> 0.3465 | M5: =IF(OR($L5="",$H5=""),"",ROUND($L5*(1-$H5),12)) -> 0.31185 | N5: =IF($M5="","",INDEX(Reference!$B$11:$B$15,MATCH($M5,Reference!$C$11:$C$15,1))) -> 3 · High | O5: =IF(OR($L5="",$I5=""),"",ROUND($L5*(1-$I5),12)) -> 0.190575 | P5: =IF($O5="","",INDEX(Reference!$B$11:$B$15,MATCH($O5,Reference!$C$11:$C$15,1))) -> 3 · High | Q5: =IF(OR($M5="",$O5=""),"",IF($M5=0,0,($M5-$O5)/$M5)) -> 0.38888889 | R5: =IF(OR($E5="",$K5="",$H5=""),"",ROUND($E5*$K5*(1-$H5),3)) -> 0.81 | S5: =IF(OR($E5="",$K5="",$I5=""),"",ROUND($E5*$K5*(1-$I5),3)) -> 0.495 | T5: =IF(OR($E5="",$K5="",$H5="",$D5=""),"",IF($D5<=0,"",$E5*$K5*(1-$H5)/($D5/Reference!$C$7))) -> 8.1 | U5: =IF($M5="","",COUNTIFS($N$5:$N$56,$N5,$R$5:$R$56,">"&$R5)+COUNTIFS($N$4:$N4,$N5,$R$4:$R4,$R5)+1) -> 1 | V5: =IF(OR($H5="",$I5=""),"",IF($I5>=1,"",IF($H5>=1,"",(1-(1-$I5)/(1-$H5))/(1-$I5)))) -> 0.70707071 | W5: =IF(OR($D5="",$D5<=0),"",MAX(0,MIN(1,(LOG10(MAX(Reference!$C$5,MIN(Reference!$C$6,$D5)))-LOG10(Reference!$C$5))/(LOG10(Reference!$C$6)-LOG10(Reference!$C$5))))) -> 0.63843778 | X5: =IF($M5="","",INDEX(Reference!$D$11:$D$15,MATCH($M5,Reference!$C$11:$C$15,1))) -> Prioritise for surveillance; fixed-interval adherence essential | Y5: =IF($O5="","",INDEX(Reference!$D$11:$D$15,MATCH($O5,Reference!$C$11:$C$15,1))) -> Prioritise for surveillance; fixed-interval adherence essential
A6: Active viral cirrhosis | B6: Table 2 | C6: 2-7%/yr | D6: 100000 | E6: 0.55 | F6: 0.7 | G6: 0.53 | H6: 0.5 | I6: 0.65 | J6: 5 | K6: =IF($J6="","",INDEX(Reference!$C$20:$C$24,$J6)) -> 1 | L6: =IF(OR($E6="",$F6="",$G6=""),"",ROUND($E6*$F6*$G6,12)) -> 0.20405 | M6: =IF(OR($L6="",$H6=""),"",ROUND($L6*(1-$H6),12)) -> 0.102025 | N6: =IF($M6="","",INDEX(Reference!$B$11:$B$15,MATCH($M6,Reference!$C$11:$C$15,1))) -> 2 · Moderate | O6: =IF(OR($L6="",$I6=""),"",ROUND($L6*(1-$I6),12)) -> 0.0714175 | P6: =IF($O6="","",INDEX(Reference!$B$11:$B$15,MATCH($O6,Reference!$C$11:$C$15,1))) -> 2 · Moderate | Q6: =IF(OR($M6="",$O6=""),"",IF($M6=0,0,($M6-$O6)/$M6)) -> 0.3 | R6: =IF(OR($E6="",$K6="",$H6=""),"",ROUND($E6*$K6*(1-$H6),3)) -> 0.275 | S6: =IF(OR($E6="",$K6="",$I6=""),"",ROUND($E6*$K6*(1-$I6),3)) -> 0.193 | T6: =IF(OR($E6="",$K6="",$H6="",$D6=""),"",IF($D6<=0,"",$E6*$K6*(1-$H6)/($D6/Reference!$C$7))) -> 2.75 | U6: =IF($M6="","",COUNTIFS($N$5:$N$56,$N6,$R$5:$R$56,">"&$R6)+COUNTIFS($N$4:$N5,$N6,$R$4:$R5,$R6)+1) -> 2 | V6: =IF(OR($H6="",$I6=""),"",IF($I6>=1,"",IF($H6>=1,"",(1-(1-$I6)/(1-$H6))/(1-$I6)))) -> 0.85714286 | W6: =IF(OR($D6="",$D6<=0),"",MAX(0,MIN(1,(LOG10(MAX(Reference!$C$5,MIN(Reference!$C$6,$D6)))-LOG10(Reference!$C$5))/(LOG10(Reference!$C$6)-LOG10(Reference!$C$5))))) -> 0.63843778 | X6: =IF($M6="","",INDEX(Reference!$D$11:$D$15,MATCH($M6,Reference!$C$11:$C$15,1))) -> Usual-care biannual surveillance appropriate; confirm adherence and recall | Y6: =IF($O6="","",INDEX(Reference!$D$11:$D$15,MATCH($O6,Reference!$C$11:$C$15,1))) -> Usual-care biannual surveillance appropriate; confirm adherence and recall
A7: Alcohol cirrhosis | B7: Table 2 | C7: 1-2.5%/yr | D7: 100000 | E7: 0.3 | F7: 0.65 | G7: 0.6 | H7: 0.2 | I7: 0.5 | J7: 5 | K7: =IF($J7="","",INDEX(Reference!$C$20:$C$24,$J7)) -> 1 | L7: =IF(OR($E7="",$F7="",$G7=""),"",ROUND($E7*$F7*$G7,12)) -> 0.117 | M7: =IF(OR($L7="",$H7=""),"",ROUND($L7*(1-$H7),12)) -> 0.0936 | N7: =IF($M7="","",INDEX(Reference!$B$11:$B$15,MATCH($M7,Reference!$C$11:$C$15,1))) -> 2 · Moderate | O7: =IF(OR($L7="",$I7=""),"",ROUND($L7*(1-$I7),12)) -> 0.0585 | P7: =IF($O7="","",INDEX(Reference!$B$11:$B$15,MATCH($O7,Reference!$C$11:$C$15,1))) -> 2 · Moderate | Q7: =IF(OR($M7="",$O7=""),"",IF($M7=0,0,($M7-$O7)/$M7)) -> 0.375 | R7: =IF(OR($E7="",$K7="",$H7=""),"",ROUND($E7*$K7*(1-$H7),3)) -> 0.24 | S7: =IF(OR($E7="",$K7="",$I7=""),"",ROUND($E7*$K7*(1-$I7),3)) -> 0.15 | T7: =IF(OR($E7="",$K7="",$H7="",$D7=""),"",IF($D7<=0,"",$E7*$K7*(1-$H7)/($D7/Reference!$C$7))) -> 2.4 | U7: =IF($M7="","",COUNTIFS($N$5:$N$56,$N7,$R$5:$R$56,">"&$R7)+COUNTIFS($N$4:$N6,$N7,$R$4:$R6,$R7)+1) -> 3 | V7: =IF(OR($H7="",$I7=""),"",IF($I7>=1,"",IF($H7>=1,"",(1-(1-$I7)/(1-$H7))/(1-$I7)))) -> 0.75 | W7: =IF(OR($D7="",$D7<=0),"",MAX(0,MIN(1,(LOG10(MAX(Reference!$C$5,MIN(Reference!$C$6,$D7)))-LOG10(Reference!$C$5))/(LOG10(Reference!$C$6)-LOG10(Reference!$C$5))))) -> 0.63843778 | X7: =IF($M7="","",INDEX(Reference!$D$11:$D$15,MATCH($M7,Reference!$C$11:$C$15,1))) -> Usual-care biannual surveillance appropriate; confirm adherence and recall | Y7: =IF($O7="","",INDEX(Reference!$D$11:$D$15,MATCH($O7,Reference!$C$11:$C$15,1))) -> Usual-care biannual surveillance appropriate; confirm adherence and recall
A8: Cured-HCV cirrhosis | B8: Table 2 | C8: ~1.8%/yr | D8: 100000 | E8: 0.25 | F8: 0.6 | G8: 0.48 | H8: 0.2 | I8: 0.55 | J8: 5 | K8: =IF($J8="","",INDEX(Reference!$C$20:$C$24,$J8)) -> 1 | L8: =IF(OR($E8="",$F8="",$G8=""),"",ROUND($E8*$F8*$G8,12)) -> 0.072 | M8: =IF(OR($L8="",$H8=""),"",ROUND($L8*(1-$H8),12)) -> 0.0576 | N8: =IF($M8="","",INDEX(Reference!$B$11:$B$15,MATCH($M8,Reference!$C$11:$C$15,1))) -> 2 · Moderate | O8: =IF(OR($L8="",$I8=""),"",ROUND($L8*(1-$I8),12)) -> 0.0324 | P8: =IF($O8="","",INDEX(Reference!$B$11:$B$15,MATCH($O8,Reference!$C$11:$C$15,1))) -> 1 · Low | Q8: =IF(OR($M8="",$O8=""),"",IF($M8=0,0,($M8-$O8)/$M8)) -> 0.4375 | R8: =IF(OR($E8="",$K8="",$H8=""),"",ROUND($E8*$K8*(1-$H8),3)) -> 0.2 | S8: =IF(OR($E8="",$K8="",$I8=""),"",ROUND($E8*$K8*(1-$I8),3)) -> 0.113 | T8: =IF(OR($E8="",$K8="",$H8="",$D8=""),"",IF($D8<=0,"",$E8*$K8*(1-$H8)/($D8/Reference!$C$7))) -> 2 | U8: =IF($M8="","",COUNTIFS($N$5:$N$56,$N8,$R$5:$R$56,">"&$R8)+COUNTIFS($N$4:$N7,$N8,$R$4:$R7,$R8)+1) -> 5 | V8: =IF(OR($H8="",$I8=""),"",IF($I8>=1,"",IF($H8>=1,"",(1-(1-$I8)/(1-$H8))/(1-$I8)))) -> 0.97222222 | W8: =IF(OR($D8="",$D8<=0),"",MAX(0,MIN(1,(LOG10(MAX(Reference!$C$5,MIN(Reference!$C$6,$D8)))-LOG10(Reference!$C$5))/(LOG10(Reference!$C$6)-LOG10(Reference!$C$5))))) -> 0.63843778 | X8: =IF($M8="","",INDEX(Reference!$D$11:$D$15,MATCH($M8,Reference!$C$11:$C$15,1))) -> Usual-care biannual surveillance appropriate; confirm adherence and recall | Y8: =IF($O8="","",INDEX(Reference!$D$11:$D$15,MATCH($O8,Reference!$C$11:$C$15,1))) -> Monitor; usual-care biannual surveillance appropriate
A9: Suppressed-HBV | B9: Table 2 | C9: ~1.25%/yr | D9: 100000 | E9: 0.2 | F9: 0.55 | G9: 0.45 | H9: 0.2 | I9: 0.55 | J9: 5 | K9: =IF($J9="","",INDEX(Reference!$C$20:$C$24,$J9)) -> 1 | L9: =IF(OR($E9="",$F9="",$G9=""),"",ROUND($E9*$F9*$G9,12)) -> 0.0495 | M9: =IF(OR($L9="",$H9=""),"",ROUND($L9*(1-$H9),12)) -> 0.0396 | N9: =IF($M9="","",INDEX(Reference!$B$11:$B$15,MATCH($M9,Reference!$C$11:$C$15,1))) -> 1 · Low | O9: =IF(OR($L9="",$I9=""),"",ROUND($L9*(1-$I9),12)) -> 0.022275 | P9: =IF($O9="","",INDEX(Reference!$B$11:$B$15,MATCH($O9,Reference!$C$11:$C$15,1))) -> 1 · Low | Q9: =IF(OR($M9="",$O9=""),"",IF($M9=0,0,($M9-$O9)/$M9)) -> 0.4375 | R9: =IF(OR($E9="",$K9="",$H9=""),"",ROUND($E9*$K9*(1-$H9),3)) -> 0.16 | S9: =IF(OR($E9="",$K9="",$I9=""),"",ROUND($E9*$K9*(1-$I9),3)) -> 0.09 | T9: =IF(OR($E9="",$K9="",$H9="",$D9=""),"",IF($D9<=0,"",$E9*$K9*(1-$H9)/($D9/Reference!$C$7))) -> 1.6 | U9: =IF($M9="","",COUNTIFS($N$5:$N$56,$N9,$R$5:$R$56,">"&$R9)+COUNTIFS($N$4:$N8,$N9,$R$4:$R8,$R9)+1) -> 1 | V9: =IF(OR($H9="",$I9=""),"",IF($I9>=1,"",IF($H9>=1,"",(1-(1-$I9)/(1-$H9))/(1-$I9)))) -> 0.97222222 | W9: =IF(OR($D9="",$D9<=0),"",MAX(0,MIN(1,(LOG10(MAX(Reference!$C$5,MIN(Reference!$C$6,$D9)))-LOG10(Reference!$C$5))/(LOG10(Reference!$C$6)-LOG10(Reference!$C$5))))) -> 0.63843778 | X9: =IF($M9="","",INDEX(Reference!$D$11:$D$15,MATCH($M9,Reference!$C$11:$C$15,1))) -> Monitor; usual-care biannual surveillance appropriate | Y9: =IF($O9="","",INDEX(Reference!$D$11:$D$15,MATCH($O9,Reference!$C$11:$C$15,1))) -> Monitor; usual-care biannual surveillance appropriate
A10: NAFLD cirrhosis | B10: Table 2 | C10: ~1.06%/yr | D10: 100000 | E10: 0.15 | F10: 0.6 | G10: 0.53 | H10: 0.2 | I10: 0.5 | J10: 5 | K10: =IF($J10="","",INDEX(Reference!$C$20:$C$24,$J10)) -> 1 | L10: =IF(OR($E10="",$F10="",$G10=""),"",ROUND($E10*$F10*$G10,12)) -> 0.0477 | M10: =IF(OR($L10="",$H10=""),"",ROUND($L10*(1-$H10),12)) -> 0.03816 | N10: =IF($M10="","",INDEX(Reference!$B$11:$B$15,MATCH($M10,Reference!$C$11:$C$15,1))) -> 1 · Low | O10: =IF(OR($L10="",$I10=""),"",ROUND($L10*(1-$I10),12)) -> 0.02385 | P10: =IF($O10="","",INDEX(Reference!$B$11:$B$15,MATCH($O10,Reference!$C$11:$C$15,1))) -> 1 · Low | Q10: =IF(OR($M10="",$O10=""),"",IF($M10=0,0,($M10-$O10)/$M10)) -> 0.375 | R10: =IF(OR($E10="",$K10="",$H10=""),"",ROUND($E10*$K10*(1-$H10),3)) -> 0.12 | S10: =IF(OR($E10="",$K10="",$I10=""),"",ROUND($E10*$K10*(1-$I10),3)) -> 0.075 | T10: =IF(OR($E10="",$K10="",$H10="",$D10=""),"",IF($D10<=0,"",$E10*$K10*(1-$H10)/($D10/Reference!$C$7))) -> 1.2 | U10: =IF($M10="","",COUNTIFS($N$5:$N$56,$N10,$R$5:$R$56,">"&$R10)+COUNTIFS($N$4:$N9,$N10,$R$4:$R9,$R10)+1) -> 3 | V10: =IF(OR($H10="",$I10=""),"",IF($I10>=1,"",IF($H10>=1,"",(1-(1-$I10)/(1-$H10))/(1-$I10)))) -> 0.75 | W10: =IF(OR($D10="",$D10<=0),"",MAX(0,MIN(1,(LOG10(MAX(Reference!$C$5,MIN(Reference!$C$6,$D10)))-LOG10(Reference!$C$5))/(LOG10(Reference!$C$6)-LOG10(Reference!$C$5))))) -> 0.63843778 | X10: =IF($M10="","",INDEX(Reference!$D$11:$D$15,MATCH($M10,Reference!$C$11:$C$15,1))) -> Monitor; usual-care biannual surveillance appropriate | Y10: =IF($O10="","",INDEX(Reference!$D$11:$D$15,MATCH($O10,Reference!$C$11:$C$15,1))) -> Monitor; usual-care biannual surveillance appropriate
A11: MASLD cirrhosis (compensated) | B11: Table 3 | C11: ~1.0%/yr | D11: 100000 | E11: 0.15 | F11: 0.6 | G11: 0.5 | H11: 0.2 | I11: 0.65 | J11: 5 | K11: =IF($J11="","",INDEX(Reference!$C$20:$C$24,$J11)) -> 1 | L11: =IF(OR($E11="",$F11="",$G11=""),"",ROUND($E11*$F11*$G11,12)) -> 0.045 | M11: =IF(OR($L11="",$H11=""),"",ROUND($L11*(1-$H11),12)) -> 0.036 | N11: =IF($M11="","",INDEX(Reference!$B$11:$B$15,MATCH($M11,Reference!$C$11:$C$15,1))) -> 1 · Low | O11: =IF(OR($L11="",$I11=""),"",ROUND($L11*(1-$I11),12)) -> 0.01575 | P11: =IF($O11="","",INDEX(Reference!$B$11:$B$15,MATCH($O11,Reference!$C$11:$C$15,1))) -> 1 · Low | Q11: =IF(OR($M11="",$O11=""),"",IF($M11=0,0,($M11-$O11)/$M11)) -> 0.5625 | R11: =IF(OR($E11="",$K11="",$H11=""),"",ROUND($E11*$K11*(1-$H11),3)) -> 0.12 | S11: =IF(OR($E11="",$K11="",$I11=""),"",ROUND($E11*$K11*(1-$I11),3)) -> 0.053 | T11: =IF(OR($E11="",$K11="",$H11="",$D11=""),"",IF($D11<=0,"",$E11*$K11*(1-$H11)/($D11/Reference!$C$7))) -> 1.2 | U11: =IF($M11="","",COUNTIFS($N$5:$N$56,$N11,$R$5:$R$56,">"&$R11)+COUNTIFS($N$4:$N10,$N11,$R$4:$R10,$R11)+1) -> 4 | V11: =IF(OR($H11="",$I11=""),"",IF($I11>=1,"",IF($H11>=1,"",(1-(1-$I11)/(1-$H11))/(1-$I11)))) -> 1.6071429 | W11: =IF(OR($D11="",$D11<=0),"",MAX(0,MIN(1,(LOG10(MAX(Reference!$C$5,MIN(Reference!$C$6,$D11)))-LOG10(Reference!$C$5))/(LOG10(Reference!$C$6)-LOG10(Reference!$C$5))))) -> 0.63843778 | X11: =IF($M11="","",INDEX(Reference!$D$11:$D$15,MATCH($M11,Reference!$C$11:$C$15,1))) -> Monitor; usual-care biannual surveillance appropriate | Y11: =IF($O11="","",INDEX(Reference!$D$11:$D$15,MATCH($O11,Reference!$C$11:$C$15,1))) -> Monitor; usual-care biannual surveillance appropriate
A12: Suppressed HBV | B12: Table 3 | C12: ~1.25%/yr | D12: 100000 | E12: 0.2 | F12: 0.6 | G12: 0.5 | H12: 0.2 | I12: 0.65 | J12: 5 | K12: =IF($J12="","",INDEX(Reference!$C$20:$C$24,$J12)) -> 1 | L12: =IF(OR($E12="",$F12="",$G12=""),"",ROUND($E12*$F12*$G12,12)) -> 0.06 | M12: =IF(OR($L12="",$H12=""),"",ROUND($L12*(1-$H12),12)) -> 0.048 | N12: =IF($M12="","",INDEX(Reference!$B$11:$B$15,MATCH($M12,Reference!$C$11:$C$15,1))) -> 1 · Low | O12: =IF(OR($L12="",$I12=""),"",ROUND($L12*(1-$I12),12)) -> 0.021 | P12: =IF($O12="","",INDEX(Reference!$B$11:$B$15,MATCH($O12,Reference!$C$11:$C$15,1))) -> 1 · Low | Q12: =IF(OR($M12="",$O12=""),"",IF($M12=0,0,($M12-$O12)/$M12)) -> 0.5625 | R12: =IF(OR($E12="",$K12="",$H12=""),"",ROUND($E12*$K12*(1-$H12),3)) -> 0.16 | S12: =IF(OR($E12="",$K12="",$I12=""),"",ROUND($E12*$K12*(1-$I12),3)) -> 0.07 | T12: =IF(OR($E12="",$K12="",$H12="",$D12=""),"",IF($D12<=0,"",$E12*$K12*(1-$H12)/($D12/Reference!$C$7))) -> 1.6 | U12: =IF($M12="","",COUNTIFS($N$5:$N$56,$N12,$R$5:$R$56,">"&$R12)+COUNTIFS($N$4:$N11,$N12,$R$4:$R11,$R12)+1) -> 2 | V12: =IF(OR($H12="",$I12=""),"",IF($I12>=1,"",IF($H12>=1,"",(1-(1-$I12)/(1-$H12))/(1-$I12)))) -> 1.6071429 | W12: =IF(OR($D12="",$D12<=0),"",MAX(0,MIN(1,(LOG10(MAX(Reference!$C$5,MIN(Reference!$C$6,$D12)))-LOG10(Reference!$C$5))/(LOG10(Reference!$C$6)-LOG10(Reference!$C$5))))) -> 0.63843778 | X12: =IF($M12="","",INDEX(Reference!$D$11:$D$15,MATCH($M12,Reference!$C$11:$C$15,1))) -> Monitor; usual-care biannual surveillance appropriate | Y12: =IF($O12="","",INDEX(Reference!$D$11:$D$15,MATCH($O12,Reference!$C$11:$C$15,1))) -> Monitor; usual-care biannual surveillance appropriate
A13: HCV post-SVR | B13: Table 3 | C13: ~1.8%/yr | D13: 100000 | E13: 0.25 | F13: 0.6 | G13: 0.5 | H13: 0.2 | I13: 0.65 | J13: 5 | K13: =IF($J13="","",INDEX(Reference!$C$20:$C$24,$J13)) -> 1 | L13: =IF(OR($E13="",$F13="",$G13=""),"",ROUND($E13*$F13*$G13,12)) -> 0.075 | M13: =IF(OR($L13="",$H13=""),"",ROUND($L13*(1-$H13),12)) -> 0.06 | N13: =IF($M13="","",INDEX(Reference!$B$11:$B$15,MATCH($M13,Reference!$C$11:$C$15,1))) -> 2 · Moderate | O13: =IF(OR($L13="",$I13=""),"",ROUND($L13*(1-$I13),12)) -> 0.02625 | P13: =IF($O13="","",INDEX(Reference!$B$11:$B$15,MATCH($O13,Reference!$C$11:$C$15,1))) -> 1 · Low | Q13: =IF(OR($M13="",$O13=""),"",IF($M13=0,0,($M13-$O13)/$M13)) -> 0.5625 | R13: =IF(OR($E13="",$K13="",$H13=""),"",ROUND($E13*$K13*(1-$H13),3)) -> 0.2 | S13: =IF(OR($E13="",$K13="",$I13=""),"",ROUND($E13*$K13*(1-$I13),3)) -> 0.088 | T13: =IF(OR($E13="",$K13="",$H13="",$D13=""),"",IF($D13<=0,"",$E13*$K13*(1-$H13)/($D13/Reference!$C$7))) -> 2 | U13: =IF($M13="","",COUNTIFS($N$5:$N$56,$N13,$R$5:$R$56,">"&$R13)+COUNTIFS($N$4:$N12,$N13,$R$4:$R12,$R13)+1) -> 6 | V13: =IF(OR($H13="",$I13=""),"",IF($I13>=1,"",IF($H13>=1,"",(1-(1-$I13)/(1-$H13))/(1-$I13)))) -> 1.6071429 | W13: =IF(OR($D13="",$D13<=0),"",MAX(0,MIN(1,(LOG10(MAX(Reference!$C$5,MIN(Reference!$C$6,$D13)))-LOG10(Reference!$C$5))/(LOG10(Reference!$C$6)-LOG10(Reference!$C$5))))) -> 0.63843778 | X13: =IF($M13="","",INDEX(Reference!$D$11:$D$15,MATCH($M13,Reference!$C$11:$C$15,1))) -> Usual-care biannual surveillance appropriate; confirm adherence and recall | Y13: =IF($O13="","",INDEX(Reference!$D$11:$D$15,MATCH($O13,Reference!$C$11:$C$15,1))) -> Monitor; usual-care biannual surveillance appropriate
A14: Alcohol cirrhosis (Pearl) | B14: Table 3 | C14: ~2%/yr | D14: 100000 | E14: 0.3 | F14: 0.6 | G14: 0.5 | H14: 0.2 | I14: 0.65 | J14: 5 | K14: =IF($J14="","",INDEX(Reference!$C$20:$C$24,$J14)) -> 1 | L14: =IF(OR($E14="",$F14="",$G14=""),"",ROUND($E14*$F14*$G14,12)) -> 0.09 | M14: =IF(OR($L14="",$H14=""),"",ROUND($L14*(1-$H14),12)) -> 0.072 | N14: =IF($M14="","",INDEX(Reference!$B$11:$B$15,MATCH($M14,Reference!$C$11:$C$15,1))) -> 2 · Moderate | O14: =IF(OR($L14="",$I14=""),"",ROUND($L14*(1-$I14),12)) -> 0.0315 | P14: =IF($O14="","",INDEX(Reference!$B$11:$B$15,MATCH($O14,Reference!$C$11:$C$15,1))) -> 1 · Low | Q14: =IF(OR($M14="",$O14=""),"",IF($M14=0,0,($M14-$O14)/$M14)) -> 0.5625 | R14: =IF(OR($E14="",$K14="",$H14=""),"",ROUND($E14*$K14*(1-$H14),3)) -> 0.24 | S14: =IF(OR($E14="",$K14="",$I14=""),"",ROUND($E14*$K14*(1-$I14),3)) -> 0.105 | T14: =IF(OR($E14="",$K14="",$H14="",$D14=""),"",IF($D14<=0,"",$E14*$K14*(1-$H14)/($D14/Reference!$C$7))) -> 2.4 | U14: =IF($M14="","",COUNTIFS($N$5:$N$56,$N14,$R$5:$R$56,">"&$R14)+COUNTIFS($N$4:$N13,$N14,$R$4:$R13,$R14)+1) -> 4 | V14: =IF(OR($H14="",$I14=""),"",IF($I14>=1,"",IF($H14>=1,"",(1-(1-$I14)/(1-$H14))/(1-$I14)))) -> 1.6071429 | W14: =IF(OR($D14="",$D14<=0),"",MAX(0,MIN(1,(LOG10(MAX(Reference!$C$5,MIN(Reference!$C$6,$D14)))-LOG10(Reference!$C$5))/(LOG10(Reference!$C$6)-LOG10(Reference!$C$5))))) -> 0.63843778 | X14: =IF($M14="","",INDEX(Reference!$D$11:$D$15,MATCH($M14,Reference!$C$11:$C$15,1))) -> Usual-care biannual surveillance appropriate; confirm adherence and recall | Y14: =IF($O14="","",INDEX(Reference!$D$11:$D$15,MATCH($O14,Reference!$C$11:$C$15,1))) -> Monitor; usual-care biannual surveillance appropriate
A15: Active viral (Pearl) | B15: Table 3 | C15: 2-7%/yr | D15: 100000 | E15: 0.55 | F15: 0.6 | G15: 0.5 | H15: 0.2 | I15: 0.65 | J15: 5 | K15: =IF($J15="","",INDEX(Reference!$C$20:$C$24,$J15)) -> 1 | L15: =IF(OR($E15="",$F15="",$G15=""),"",ROUND($E15*$F15*$G15,12)) -> 0.165 | M15: =IF(OR($L15="",$H15=""),"",ROUND($L15*(1-$H15),12)) -> 0.132 | N15: =IF($M15="","",INDEX(Reference!$B$11:$B$15,MATCH($M15,Reference!$C$11:$C$15,1))) -> 2 · Moderate | O15: =IF(OR($L15="",$I15=""),"",ROUND($L15*(1-$I15),12)) -> 0.05775 | P15: =IF($O15="","",INDEX(Reference!$B$11:$B$15,MATCH($O15,Reference!$C$11:$C$15,1))) -> 2 · Moderate | Q15: =IF(OR($M15="",$O15=""),"",IF($M15=0,0,($M15-$O15)/$M15)) -> 0.5625 | R15: =IF(OR($E15="",$K15="",$H15=""),"",ROUND($E15*$K15*(1-$H15),3)) -> 0.44 | S15: =IF(OR($E15="",$K15="",$I15=""),"",ROUND($E15*$K15*(1-$I15),3)) -> 0.193 | T15: =IF(OR($E15="",$K15="",$H15="",$D15=""),"",IF($D15<=0,"",$E15*$K15*(1-$H15)/($D15/Reference!$C$7))) -> 4.4 | U15: =IF($M15="","",COUNTIFS($N$5:$N$56,$N15,$R$5:$R$56,">"&$R15)+COUNTIFS($N$4:$N14,$N15,$R$4:$R14,$R15)+1) -> 1 | V15: =IF(OR($H15="",$I15=""),"",IF($I15>=1,"",IF($H15>=1,"",(1-(1-$I15)/(1-$H15))/(1-$I15)))) -> 1.6071429 | W15: =IF(OR($D15="",$D15<=0),"",MAX(0,MIN(1,(LOG10(MAX(Reference!$C$5,MIN(Reference!$C$6,$D15)))-LOG10(Reference!$C$5))/(LOG10(Reference!$C$6)-LOG10(Reference!$C$5))))) -> 0.63843778 | X15: =IF($M15="","",INDEX(Reference!$D$11:$D$15,MATCH($M15,Reference!$C$11:$C$15,1))) -> Usual-care biannual surveillance appropriate; confirm adherence and recall | Y15: =IF($O15="","",INDEX(Reference!$D$11:$D$15,MATCH($O15,Reference!$C$11:$C$15,1))) -> Usual-care biannual surveillance appropriate; confirm adherence and recall
A16: High-burden MASLD | B16: Table 3 | C16: ~5%/yr | D16: 100000 | E16: 0.65 | F16: 0.6 | G16: 0.5 | H16: 0.2 | I16: 0.65 | J16: 5 | K16: =IF($J16="","",INDEX(Reference!$C$20:$C$24,$J16)) -> 1 | L16: =IF(OR($E16="",$F16="",$G16=""),"",ROUND($E16*$F16*$G16,12)) -> 0.195 | M16: =IF(OR($L16="",$H16=""),"",ROUND($L16*(1-$H16),12)) -> 0.156 | N16: =IF($M16="","",INDEX(Reference!$B$11:$B$15,MATCH($M16,Reference!$C$11:$C$15,1))) -> 3 · High | O16: =IF(OR($L16="",$I16=""),"",ROUND($L16*(1-$I16),12)) -> 0.06825 | P16: =IF($O16="","",INDEX(Reference!$B$11:$B$15,MATCH($O16,Reference!$C$11:$C$15,1))) -> 2 · Moderate | Q16: =IF(OR($M16="",$O16=""),"",IF($M16=0,0,($M16-$O16)/$M16)) -> 0.5625 | R16: =IF(OR($E16="",$K16="",$H16=""),"",ROUND($E16*$K16*(1-$H16),3)) -> 0.52 | S16: =IF(OR($E16="",$K16="",$I16=""),"",ROUND($E16*$K16*(1-$I16),3)) -> 0.228 | T16: =IF(OR($E16="",$K16="",$H16="",$D16=""),"",IF($D16<=0,"",$E16*$K16*(1-$H16)/($D16/Reference!$C$7))) -> 5.2 | U16: =IF($M16="","",COUNTIFS($N$5:$N$56,$N16,$R$5:$R$56,">"&$R16)+COUNTIFS($N$4:$N15,$N16,$R$4:$R15,$R16)+1) -> 2 | V16: =IF(OR($H16="",$I16=""),"",IF($I16>=1,"",IF($H16>=1,"",(1-(1-$I16)/(1-$H16))/(1-$I16)))) -> 1.6071429 | W16: =IF(OR($D16="",$D16<=0),"",MAX(0,MIN(1,(LOG10(MAX(Reference!$C$5,MIN(Reference!$C$6,$D16)))-LOG10(Reference!$C$5))/(LOG10(Reference!$C$6)-LOG10(Reference!$C$5))))) -> 0.63843778 | X16: =IF($M16="","",INDEX(Reference!$D$11:$D$15,MATCH($M16,Reference!$C$11:$C$15,1))) -> Prioritise for surveillance; fixed-interval adherence essential | Y16: =IF($O16="","",INDEX(Reference!$D$11:$D$15,MATCH($O16,Reference!$C$11:$C$15,1))) -> Usual-care biannual surveillance appropriate; confirm adherence and recall
... A18: Patient B — alcohol-related, marginal reserve | B18: Worked example | C18: ~25% (illustrative) | D18: 100000 | E18: 0.25 | F18: 0.6 | G18: 0.55 | H18: 0.2 | I18: 0.2 | J18: 5 | K18: =IF($J18="","",INDEX(Reference!$C$20:$C$24,$J18)) -> 1 | L18: =IF(OR($E18="",$F18="",$G18=""),"",ROUND($E18*$F18*$G18,12)) -> 0.0825 | M18: =IF(OR($L18="",$H18=""),"",ROUND($L18*(1-$H18),12)) -> 0.066 | N18: =IF($M18="","",INDEX(Reference!$B$11:$B$15,MATCH($M18,Reference!$C$11:$C$15,1))) -> 2 · Moderate | O18: =IF(OR($L18="",$I18=""),"",ROUND($L18*(1-$I18),12)) -> 0.066 | P18: =IF($O18="","",INDEX(Reference!$B$11:$B$15,MATCH($O18,Reference!$C$11:$C$15,1))) -> 2 · Moderate | Q18: =IF(OR($M18="",$O18=""),"",IF($M18=0,0,($M18-$O18)/$M18)) -> 0 | R18: =IF(OR($E18="",$K18="",$H18=""),"",ROUND($E18*$K18*(1-$H18),3)) -> 0.2 | S18: =IF(OR($E18="",$K18="",$I18=""),"",ROUND($E18*$K18*(1-$I18),3)) -> 0.2 | T18: =IF(OR($E18="",$K18="",$H18="",$D18=""),"",IF($D18<=0,"",$E18*$K18*(1-$H18)/($D18/Reference!$C$7))) -> 2 | U18: =IF($M18="","",COUNTIFS($N$5:$N$56,$N18,$R$5:$R$56,">"&$R18)+COUNTIFS($N$4:$N17,$N18,$R$4:$R17,$R18)+1) -> 7 | V18: =IF(OR($H18="",$I18=""),"",IF($I18>=1,"",IF($H18>=1,"",(1-(1-$I18)/(1-$H18))/(1-$I18)))) -> 0 | W18: =IF(OR($D18="",$D18<=0),"",MAX(0,MIN(1,(LOG10(MAX(Reference!$C$5,MIN(Reference!$C$6,$D18)))-LOG10(Reference!$C$5))/(LOG10(Reference!$C$6)-LOG10(Reference!$C$5))))) -> 0.63843778 | X18: =IF($M18="","",INDEX(Reference!$D$11:$D$15,MATCH($M18,Reference!$C$11:$C$15,1))) -> Usual-care biannual surveillance appropriate; confirm adherence and recall | Y18: =IF($O18="","",INDEX(Reference!$D$11:$D$15,MATCH($O18,Reference!$C$11:$C$15,1))) -> Usual-care biannual surveillance appropriate; confirm adherence and recall
K19: =IF($J19="","",INDEX(Reference!$C$20:$C$24,$J19)) | L19: =IF(OR($E19="",$F19="",$G19=""),"",ROUND($E19*$F19*$G19,12)) | M19: =IF(OR($L19="",$H19=""),"",ROUND($L19*(1-$H19),12)) | N19: =IF($M19="","",INDEX(Reference!$B$11:$B$15,MATCH($M19,Reference!$C$11:$C$15,1))) | O19: =IF(OR($L19="",$I19=""),"",ROUND($L19*(1-$I19),12)) | P19: =IF($O19="","",INDEX(Reference!$B$11:$B$15,MATCH($O19,Reference!$C$11:$C$15,1))) | Q19: =IF(OR($M19="",$O19=""),"",IF($M19=0,0,($M19-$O19)/$M19)) | R19: =IF(OR($E19="",$K19="",$H19=""),"",ROUND($E19*$K19*(1-$H19),3)) | S19: =IF(OR($E19="",$K19="",$I19=""),"",ROUND($E19*$K19*(1-$I19),3)) | T19: =IF(OR($E19="",$K19="",$H19="",$D19=""),"",IF($D19<=0,"",$E19*$K19*(1-$H19)/($D19/Reference!$C$7))) | U19: =IF($M19="","",COUNTIFS($N$5:$N$56,$N19,$R$5:$R$56,">"&$R19)+COUNTIFS($N$4:$N18,$N19,$R$4:$R18,$R19)+1) | V19: =IF(OR($H19="",$I19=""),"",IF($I19>=1,"",IF($H19>=1,"",(1-(1-$I19)/(1-$H19))/(1-$I19)))) | W19: =IF(OR($D19="",$D19<=0),"",MAX(0,MIN(1,(LOG10(MAX(Reference!$C$5,MIN(Reference!$C$6,$D19)))-LOG10(Reference!$C$5))/(LOG10(Reference!$C$6)-LOG10(Reference!$C$5))))) | X19: =IF($M19="","",INDEX(Reference!$D$11:$D$15,MATCH($M19,Reference!$C$11:$C$15,1))) | Y19: =IF($O19="","",INDEX(Reference!$D$11:$D$15,MATCH($O19,Reference!$C$11:$C$15,1)))
K20: =IF($J20="","",INDEX(Reference!$C$20:$C$24,$J20)) | L20: =IF(OR($E20="",$F20="",$G20=""),"",ROUND($E20*$F20*$G20,12)) | M20: =IF(OR($L20="",$H20=""),"",ROUND($L20*(1-$H20),12)) | N20: =IF($M20="","",INDEX(Reference!$B$11:$B$15,MATCH($M20,Reference!$C$11:$C$15,1))) | O20: =IF(OR($L20="",$I20=""),"",ROUND($L20*(1-$I20),12)) | P20: =IF($O20="","",INDEX(Reference!$B$11:$B$15,MATCH($O20,Reference!$C$11:$C$15,1))) | Q20: =IF(OR($M20="",$O20=""),"",IF($M20=0,0,($M20-$O20)/$M20)) | R20: =IF(OR($E20="",$K20="",$H20=""),"",ROUND($E20*$K20*(1-$H20),3)) | S20: =IF(OR($E20="",$K20="",$I20=""),"",ROUND($E20*$K20*(1-$I20),3)) | T20: =IF(OR($E20="",$K20="",$H20="",$D20=""),"",IF($D20<=0,"",$E20*$K20*(1-$H20)/($D20/Reference!$C$7))) | U20: =IF($M20="","",COUNTIFS($N$5:$N$56,$N20,$R$5:$R$56,">"&$R20)+COUNTIFS($N$4:$N19,$N20,$R$4:$R19,$R20)+1) | V20: =IF(OR($H20="",$I20=""),"",IF($I20>=1,"",IF($H20>=1,"",(1-(1-$I20)/(1-$H20))/(1-$I20)))) | W20: =IF(OR($D20="",$D20<=0),"",MAX(0,MIN(1,(LOG10(MAX(Reference!$C$5,MIN(Reference!$C$6,$D20)))-LOG10(Reference!$C$5))/(LOG10(Reference!$C$6)-LOG10(Reference!$C$5))))) | X20: =IF($M20="","",INDEX(Reference!$D$11:$D$15,MATCH($M20,Reference!$C$11:$C$15,1))) | Y20: =IF($O20="","",INDEX(Reference!$D$11:$D$15,MATCH($O20,Reference!$C$11:$C$15,1)))
K21: =IF($J21="","",INDEX(Reference!$C$20:$C$24,$J21)) | L21: =IF(OR($E21="",$F21="",$G21=""),"",ROUND($E21*$F21*$G21,12)) | M21: =IF(OR($L21="",$H21=""),"",ROUND($L21*(1-$H21),12)) | N21: =IF($M21="","",INDEX(Reference!$B$11:$B$15,MATCH($M21,Reference!$C$11:$C$15,1))) | O21: =IF(OR($L21="",$I21=""),"",ROUND($L21*(1-$I21),12)) | P21: =IF($O21="","",INDEX(Reference!$B$11:$B$15,MATCH($O21,Reference!$C$11:$C$15,1))) | Q21: =IF(OR($M21="",$O21=""),"",IF($M21=0,0,($M21-$O21)/$M21)) | R21: =IF(OR($E21="",$K21="",$H21=""),"",ROUND($E21*$K21*(1-$H21),3)) | S21: =IF(OR($E21="",$K21="",$I21=""),"",ROUND($E21*$K21*(1-$I21),3)) | T21: =IF(OR($E21="",$K21="",$H21="",$D21=""),"",IF($D21<=0,"",$E21*$K21*(1-$H21)/($D21/Reference!$C$7))) | U21: =IF($M21="","",COUNTIFS($N$5:$N$56,$N21,$R$5:$R$56,">"&$R21)+COUNTIFS($N$4:$N20,$N21,$R$4:$R20,$R21)+1) | V21: =IF(OR($H21="",$I21=""),"",IF($I21>=1,"",IF($H21>=1,"",(1-(1-$I21)/(1-$H21))/(1-$I21)))) | W21: =IF(OR($D21="",$D21<=0),"",MAX(0,MIN(1,(LOG10(MAX(Reference!$C$5,MIN(Reference!$C$6,$D21)))-LOG10(Reference!$C$5))/(LOG10(Reference!$C$6)-LOG10(Reference!$C$5))))) | X21: =IF($M21="","",INDEX(Reference!$D$11:$D$15,MATCH($M21,Reference!$C$11:$C$15,1))) | Y21: =IF($O21="","",INDEX(Reference!$D$11:$D$15,MATCH($O21,Reference!$C$11:$C$15,1)))
K22: =IF($J22="","",INDEX(Reference!$C$20:$C$24,$J22)) | L22: =IF(OR($E22="",$F22="",$G22=""),"",ROUND($E22*$F22*$G22,12)) | M22: =IF(OR($L22="",$H22=""),"",ROUND($L22*(1-$H22),12)) | N22: =IF($M22="","",INDEX(Reference!$B$11:$B$15,MATCH($M22,Reference!$C$11:$C$15,1))) | O22: =IF(OR($L22="",$I22=""),"",ROUND($L22*(1-$I22),12)) | P22: =IF($O22="","",INDEX(Reference!$B$11:$B$15,MATCH($O22,Reference!$C$11:$C$15,1))) | Q22: =IF(OR($M22="",$O22=""),"",IF($M22=0,0,($M22-$O22)/$M22)) | R22: =IF(OR($E22="",$K22="",$H22=""),"",ROUND($E22*$K22*(1-$H22),3)) | S22: =IF(OR($E22="",$K22="",$I22=""),"",ROUND($E22*$K22*(1-$I22),3)) | T22: =IF(OR($E22="",$K22="",$H22="",$D22=""),"",IF($D22<=0,"",$E22*$K22*(1-$H22)/($D22/Reference!$C$7))) | U22: =IF($M22="","",COUNTIFS($N$5:$N$56,$N22,$R$5:$R$56,">"&$R22)+COUNTIFS($N$4:$N21,$N22,$R$4:$R21,$R22)+1) | V22: =IF(OR($H22="",$I22=""),"",IF($I22>=1,"",IF($H22>=1,"",(1-(1-$I22)/(1-$H22))/(1-$I22)))) | W22: =IF(OR($D22="",$D22<=0),"",MAX(0,MIN(1,(LOG10(MAX(Reference!$C$5,MIN(Reference!$C$6,$D22)))-LOG10(Reference!$C$5))/(LOG10(Reference!$C$6)-LOG10(Reference!$C$5))))) | X22: =IF($M22="","",INDEX(Reference!$D$11:$D$15,MATCH($M22,Reference!$C$11:$C$15,1))) | Y22: =IF($O22="","",INDEX(Reference!$D$11:$D$15,MATCH($O22,Reference!$C$11:$C$15,1)))
K23: =IF($J23="","",INDEX(Reference!$C$20:$C$24,$J23)) | L23: =IF(OR($E23="",$F23="",$G23=""),"",ROUND($E23*$F23*$G23,12)) | M23: =IF(OR($L23="",$H23=""),"",ROUND($L23*(1-$H23),12)) | N23: =IF($M23="","",INDEX(Reference!$B$11:$B$15,MATCH($M23,Reference!$C$11:$C$15,1))) | O23: =IF(OR($L23="",$I23=""),"",ROUND($L23*(1-$I23),12)) | P23: =IF($O23="","",INDEX(Reference!$B$11:$B$15,MATCH($O23,Reference!$C$11:$C$15,1))) | Q23: =IF(OR($M23="",$O23=""),"",IF($M23=0,0,($M23-$O23)/$M23)) | R23: =IF(OR($E23="",$K23="",$H23=""),"",ROUND($E23*$K23*(1-$H23),3)) | S23: =IF(OR($E23="",$K23="",$I23=""),"",ROUND($E23*$K23*(1-$I23),3)) | T23: =IF(OR($E23="",$K23="",$H23="",$D23=""),"",IF($D23<=0,"",$E23*$K23*(1-$H23)/($D23/Reference!$C$7))) | U23: =IF($M23="","",COUNTIFS($N$5:$N$56,$N23,$R$5:$R$56,">"&$R23)+COUNTIFS($N$4:$N22,$N23,$R$4:$R22,$R23)+1) | V23: =IF(OR($H23="",$I23=""),"",IF($I23>=1,"",IF($H23>=1,"",(1-(1-$I23)/(1-$H23))/(1-$I23)))) | W23: =IF(OR($D23="",$D23<=0),"",MAX(0,MIN(1,(LOG10(MAX(Reference!$C$5,MIN(Reference!$C$6,$D23)))-LOG10(Reference!$C$5))/(LOG10(Reference!$C$6)-LOG10(Reference!$C$5))))) | X23: =IF($M23="","",INDEX(Reference!$D$11:$D$15,MATCH($M23,Reference!$C$11:$C$15,1))) | Y23: =IF($O23="","",INDEX(Reference!$D$11:$D$15,MATCH($O23,Reference!$C$11:$C$15,1)))
K24: =IF($J24="","",INDEX(Reference!$C$20:$C$24,$J24)) | L24: =IF(OR($E24="",$F24="",$G24=""),"",ROUND($E24*$F24*$G24,12)) | M24: =IF(OR($L24="",$H24=""),"",ROUND($L24*(1-$H24),12)) | N24: =IF($M24="","",INDEX(Reference!$B$11:$B$15,MATCH($M24,Reference!$C$11:$C$15,1))) | O24: =IF(OR($L24="",$I24=""),"",ROUND($L24*(1-$I24),12)) | P24: =IF($O24="","",INDEX(Reference!$B$11:$B$15,MATCH($O24,Reference!$C$11:$C$15,1))) | Q24: =IF(OR($M24="",$O24=""),"",IF($M24=0,0,($M24-$O24)/$M24)) | R24: =IF(OR($E24="",$K24="",$H24=""),"",ROUND($E24*$K24*(1-$H24),3)) | S24: =IF(OR($E24="",$K24="",$I24=""),"",ROUND($E24*$K24*(1-$I24),3)) | T24: =IF(OR($E24="",$K24="",$H24="",$D24=""),"",IF($D24<=0,"",$E24*$K24*(1-$H24)/($D24/Reference!$C$7))) | U24: =IF($M24="","",COUNTIFS($N$5:$N$56,$N24,$R$5:$R$56,">"&$R24)+COUNTIFS($N$4:$N23,$N24,$R$4:$R23,$R24)+1) | V24: =IF(OR($H24="",$I24=""),"",IF($I24>=1,"",IF($H24>=1,"",(1-(1-$I24)/(1-$H24))/(1-$I24)))) | W24: =IF(OR($D24="",$D24<=0),"",MAX(0,MIN(1,(LOG10(MAX(Reference!$C$5,MIN(Reference!$C$6,$D24)))-LOG10(Reference!$C$5))/(LOG10(Reference!$C$6)-LOG10(Reference!$C$5))))) | X24: =IF($M24="","",INDEX(Reference!$D$11:$D$15,MATCH($M24,Reference!$C$11:$C$15,1))) | Y24: =IF($O24="","",INDEX(Reference!$D$11:$D$15,MATCH($O24,Reference!$C$11:$C$15,1)))
K25: =IF($J25="","",INDEX(Reference!$C$20:$C$24,$J25)) | L25: =IF(OR($E25="",$F25="",$G25=""),"",ROUND($E25*$F25*$G25,12)) | M25: =IF(OR($L25="",$H25=""),"",ROUND($L25*(1-$H25),12)) | N25: =IF($M25="","",INDEX(Reference!$B$11:$B$15,MATCH($M25,Reference!$C$11:$C$15,1))) | O25: =IF(OR($L25="",$I25=""),"",ROUND($L25*(1-$I25),12)) | P25: =IF($O25="","",INDEX(Reference!$B$11:$B$15,MATCH($O25,Reference!$C$11:$C$15,1))) | Q25: =IF(OR($M25="",$O25=""),"",IF($M25=0,0,($M25-$O25)/$M25)) | R25: =IF(OR($E25="",$K25="",$H25=""),"",ROUND($E25*$K25*(1-$H25),3)) | S25: =IF(OR($E25="",$K25="",$I25=""),"",ROUND($E25*$K25*(1-$I25),3)) | T25: =IF(OR($E25="",$K25="",$H25="",$D25=""),"",IF($D25<=0,"",$E25*$K25*(1-$H25)/($D25/Reference!$C$7))) | U25: =IF($M25="","",COUNTIFS($N$5:$N$56,$N25,$R$5:$R$56,">"&$R25)+COUNTIFS($N$4:$N24,$N25,$R$4:$R24,$R25)+1) | V25: =IF(OR($H25="",$I25=""),"",IF($I25>=1,"",IF($H25>=1,"",(1-(1-$I25)/(1-$H25))/(1-$I25)))) | W25: =IF(OR($D25="",$D25<=0),"",MAX(0,MIN(1,(LOG10(MAX(Reference!$C$5,MIN(Reference!$C$6,$D25)))-LOG10(Reference!$C$5))/(LOG10(Reference!$C$6)-LOG10(Reference!$C$5))))) | X25: =IF($M25="","",INDEX(Reference!$D$11:$D$15,MATCH($M25,Reference!$C$11:$C$15,1))) | Y25: =IF($O25="","",INDEX(Reference!$D$11:$D$15,MATCH($O25,Reference!$C$11:$C$15,1)))
K26: =IF($J26="","",INDEX(Reference!$C$20:$C$24,$J26)) | L26: =IF(OR($E26="",$F26="",$G26=""),"",ROUND($E26*$F26*$G26,12)) | M26: =IF(OR($L26="",$H26=""),"",ROUND($L26*(1-$H26),12)) | N26: =IF($M26="","",INDEX(Reference!$B$11:$B$15,MATCH($M26,Reference!$C$11:$C$15,1))) | O26: =IF(OR($L26="",$I26=""),"",ROUND($L26*(1-$I26),12)) | P26: =IF($O26="","",INDEX(Reference!$B$11:$B$15,MATCH($O26,Reference!$C$11:$C$15,1))) | Q26: =IF(OR($M26="",$O26=""),"",IF($M26=0,0,($M26-$O26)/$M26)) | R26: =IF(OR($E26="",$K26="",$H26=""),"",ROUND($E26*$K26*(1-$H26),3)) | S26: =IF(OR($E26="",$K26="",$I26=""),"",ROUND($E26*$K26*(1-$I26),3)) | T26: =IF(OR($E26="",$K26="",$H26="",$D26=""),"",IF($D26<=0,"",$E26*$K26*(1-$H26)/($D26/Reference!$C$7))) | U26: =IF($M26="","",COUNTIFS($N$5:$N$56,$N26,$R$5:$R$56,">"&$R26)+COUNTIFS($N$4:$N25,$N26,$R$4:$R25,$R26)+1) | V26: =IF(OR($H26="",$I26=""),"",IF($I26>=1,"",IF($H26>=1,"",(1-(1-$I26)/(1-$H26))/(1-$I26)))) | W26: =IF(OR($D26="",$D26<=0),"",MAX(0,MIN(1,(LOG10(MAX(Reference!$C$5,MIN(Reference!$C$6,$D26)))-LOG10(Reference!$C$5))/(LOG10(Reference!$C$6)-LOG10(Reference!$C$5))))) | X26: =IF($M26="","",INDEX(Reference!$D$11:$D$15,MATCH($M26,Reference!$C$11:$C$15,1))) | Y26: =IF($O26="","",INDEX(Reference!$D$11:$D$15,MATCH($O26,Reference!$C$11:$C$15,1)))
K27: =IF($J27="","",INDEX(Reference!$C$20:$C$24,$J27)) | L27: =IF(OR($E27="",$F27="",$G27=""),"",ROUND($E27*$F27*$G27,12)) | M27: =IF(OR($L27="",$H27=""),"",ROUND($L27*(1-$H27),12)) | N27: =IF($M27="","",INDEX(Reference!$B$11:$B$15,MATCH($M27,Reference!$C$11:$C$15,1))) | O27: =IF(OR($L27="",$I27=""),"",ROUND($L27*(1-$I27),12)) | P27: =IF($O27="","",INDEX(Reference!$B$11:$B$15,MATCH($O27,Reference!$C$11:$C$15,1))) | Q27: =IF(OR($M27="",$O27=""),"",IF($M27=0,0,($M27-$O27)/$M27)) | R27: =IF(OR($E27="",$K27="",$H27=""),"",ROUND($E27*$K27*(1-$H27),3)) | S27: =IF(OR($E27="",$K27="",$I27=""),"",ROUND($E27*$K27*(1-$I27),3)) | T27: =IF(OR($E27="",$K27="",$H27="",$D27=""),"",IF($D27<=0,"",$E27*$K27*(1-$H27)/($D27/Reference!$C$7))) | U27: =IF($M27="","",COUNTIFS($N$5:$N$56,$N27,$R$5:$R$56,">"&$R27)+COUNTIFS($N$4:$N26,$N27,$R$4:$R26,$R27)+1) | V27: =IF(OR($H27="",$I27=""),"",IF($I27>=1,"",IF($H27>=1,"",(1-(1-$I27)/(1-$H27))/(1-$I27)))) | W27: =IF(OR($D27="",$D27<=0),"",MAX(0,MIN(1,(LOG10(MAX(Reference!$C$5,MIN(Reference!$C$6,$D27)))-LOG10(Reference!$C$5))/(LOG10(Reference!$C$6)-LOG10(Reference!$C$5))))) | X27: =IF($M27="","",INDEX(Reference!$D$11:$D$15,MATCH($M27,Reference!$C$11:$C$15,1))) | Y27: =IF($O27="","",INDEX(Reference!$D$11:$D$15,MATCH($O27,Reference!$C$11:$C$15,1)))
K28: =IF($J28="","",INDEX(Reference!$C$20:$C$24,$J28)) | L28: =IF(OR($E28="",$F28="",$G28=""),"",ROUND($E28*$F28*$G28,12)) | M28: =IF(OR($L28="",$H28=""),"",ROUND($L28*(1-$H28),12)) | N28: =IF($M28="","",INDEX(Reference!$B$11:$B$15,MATCH($M28,Reference!$C$11:$C$15,1))) | O28: =IF(OR($L28="",$I28=""),"",ROUND($L28*(1-$I28),12)) | P28: =IF($O28="","",INDEX(Reference!$B$11:$B$15,MATCH($O28,Reference!$C$11:$C$15,1))) | Q28: =IF(OR($M28="",$O28=""),"",IF($M28=0,0,($M28-$O28)/$M28)) | R28: =IF(OR($E28="",$K28="",$H28=""),"",ROUND($E28*$K28*(1-$H28),3)) | S28: =IF(OR($E28="",$K28="",$I28=""),"",ROUND($E28*$K28*(1-$I28),3)) | T28: =IF(OR($E28="",$K28="",$H28="",$D28=""),"",IF($D28<=0,"",$E28*$K28*(1-$H28)/($D28/Reference!$C$7))) | U28: =IF($M28="","",COUNTIFS($N$5:$N$56,$N28,$R$5:$R$56,">"&$R28)+COUNTIFS($N$4:$N27,$N28,$R$4:$R27,$R28)+1) | V28: =IF(OR($H28="",$I28=""),"",IF($I28>=1,"",IF($H28>=1,"",(1-(1-$I28)/(1-$H28))/(1-$I28)))) | W28: =IF(OR($D28="",$D28<=0),"",MAX(0,MIN(1,(LOG10(MAX(Reference!$C$5,MIN(Reference!$C$6,$D28)))-LOG10(Reference!$C$5))/(LOG10(Reference!$C$6)-LOG10(Reference!$C$5))))) | X28: =IF($M28="","",INDEX(Reference!$D$11:$D$15,MATCH($M28,Reference!$C$11:$C$15,1))) | Y28: =IF($O28="","",INDEX(Reference!$D$11:$D$15,MATCH($O28,Reference!$C$11:$C$15,1)))
K29: =IF($J29="","",INDEX(Reference!$C$20:$C$24,$J29)) | L29: =IF(OR($E29="",$F29="",$G29=""),"",ROUND($E29*$F29*$G29,12)) | M29: =IF(OR($L29="",$H29=""),"",ROUND($L29*(1-$H29),12)) | N29: =IF($M29="","",INDEX(Reference!$B$11:$B$15,MATCH($M29,Reference!$C$11:$C$15,1))) | O29: =IF(OR($L29="",$I29=""),"",ROUND($L29*(1-$I29),12)) | P29: =IF($O29="","",INDEX(Reference!$B$11:$B$15,MATCH($O29,Reference!$C$11:$C$15,1))) | Q29: =IF(OR($M29="",$O29=""),"",IF($M29=0,0,($M29-$O29)/$M29)) | R29: =IF(OR($E29="",$K29="",$H29=""),"",ROUND($E29*$K29*(1-$H29),3)) | S29: =IF(OR($E29="",$K29="",$I29=""),"",ROUND($E29*$K29*(1-$I29),3)) | T29: =IF(OR($E29="",$K29="",$H29="",$D29=""),"",IF($D29<=0,"",$E29*$K29*(1-$H29)/($D29/Reference!$C$7))) | U29: =IF($M29="","",COUNTIFS($N$5:$N$56,$N29,$R$5:$R$56,">"&$R29)+COUNTIFS($N$4:$N28,$N29,$R$4:$R28,$R29)+1) | V29: =IF(OR($H29="",$I29=""),"",IF($I29>=1,"",IF($H29>=1,"",(1-(1-$I29)/(1-$H29))/(1-$I29)))) | W29: =IF(OR($D29="",$D29<=0),"",MAX(0,MIN(1,(LOG10(MAX(Reference!$C$5,MIN(Reference!$C$6,$D29)))-LOG10(Reference!$C$5))/(LOG10(Reference!$C$6)-LOG10(Reference!$C$5))))) | X29: =IF($M29="","",INDEX(Reference!$D$11:$D$15,MATCH($M29,Reference!$C$11:$C$15,1))) | Y29: =IF($O29="","",INDEX(Reference!$D$11:$D$15,MATCH($O29,Reference!$C$11:$C$15,1)))
K30: =IF($J30="","",INDEX(Reference!$C$20:$C$24,$J30)) | L30: =IF(OR($E30="",$F30="",$G30=""),"",ROUND($E30*$F30*$G30,12)) | M30: =IF(OR($L30="",$H30=""),"",ROUND($L30*(1-$H30),12)) | N30: =IF($M30="","",INDEX(Reference!$B$11:$B$15,MATCH($M30,Reference!$C$11:$C$15,1))) | O30: =IF(OR($L30="",$I30=""),"",ROUND($L30*(1-$I30),12)) | P30: =IF($O30="","",INDEX(Reference!$B$11:$B$15,MATCH($O30,Reference!$C$11:$C$15,1))) | Q30: =IF(OR($M30="",$O30=""),"",IF($M30=0,0,($M30-$O30)/$M30)) | R30: =IF(OR($E30="",$K30="",$H30=""),"",ROUND($E30*$K30*(1-$H30),3)) | S30: =IF(OR($E30="",$K30="",$I30=""),"",ROUND($E30*$K30*(1-$I30),3)) | T30: =IF(OR($E30="",$K30="",$H30="",$D30=""),"",IF($D30<=0,"",$E30*$K30*(1-$H30)/($D30/Reference!$C$7))) | U30: =IF($M30="","",COUNTIFS($N$5:$N$56,$N30,$R$5:$R$56,">"&$R30)+COUNTIFS($N$4:$N29,$N30,$R$4:$R29,$R30)+1) | V30: =IF(OR($H30="",$I30=""),"",IF($I30>=1,"",IF($H30>=1,"",(1-(1-$I30)/(1-$H30))/(1-$I30)))) | W30: =IF(OR($D30="",$D30<=0),"",MAX(0,MIN(1,(LOG10(MAX(Reference!$C$5,MIN(Reference!$C$6,$D30)))-LOG10(Reference!$C$5))/(LOG10(Reference!$C$6)-LOG10(Reference!$C$5))))) | X30: =IF($M30="","",INDEX(Reference!$D$11:$D$15,MATCH($M30,Reference!$C$11:$C$15,1))) | Y30: =IF($O30="","",INDEX(Reference!$D$11:$D$15,MATCH($O30,Reference!$C$11:$C$15,1)))
... K56: =IF($J56="","",INDEX(Reference!$C$20:$C$24,$J56)) | L56: =IF(OR($E56="",$F56="",$G56=""),"",ROUND($E56*$F56*$G56,12)) | M56: =IF(OR($L56="",$H56=""),"",ROUND($L56*(1-$H56),12)) | N56: =IF($M56="","",INDEX(Reference!$B$11:$B$15,MATCH($M56,Reference!$C$11:$C$15,1))) | O56: =IF(OR($L56="",$I56=""),"",ROUND($L56*(1-$I56),12)) | P56: =IF($O56="","",INDEX(Reference!$B$11:$B$15,MATCH($O56,Reference!$C$11:$C$15,1))) | Q56: =IF(OR($M56="",$O56=""),"",IF($M56=0,0,($M56-$O56)/$M56)) | R56: =IF(OR($E56="",$K56="",$H56=""),"",ROUND($E56*$K56*(1-$H56),3)) | S56: =IF(OR($E56="",$K56="",$I56=""),"",ROUND($E56*$K56*(1-$I56),3)) | T56: =IF(OR($E56="",$K56="",$H56="",$D56=""),"",IF($D56<=0,"",$E56*$K56*(1-$H56)/($D56/Reference!$C$7))) | U56: =IF($M56="","",COUNTIFS($N$5:$N$56,$N56,$R$5:$R$56,">"&$R56)+COUNTIFS($N$4:$N55,$N56,$R$4:$R55,$R56)+1) | V56: =IF(OR($H56="",$I56=""),"",IF($I56>=1,"",IF($H56>=1,"",(1-(1-$I56)/(1-$H56))/(1-$I56)))) | W56: =IF(OR($D56="",$D56<=0),"",MAX(0,MIN(1,(LOG10(MAX(Reference!$C$5,MIN(Reference!$C$6,$D56)))-LOG10(Reference!$C$5))/(LOG10(Reference!$C$6)-LOG10(Reference!$C$5))))) | X56: =IF($M56="","",INDEX(Reference!$D$11:$D$15,MATCH($M56,Reference!$C$11:$C$15,1))) | Y56: =IF($O56="","",INDEX(Reference!$D$11:$D$15,MATCH($O56,Reference!$C$11:$C$15,1)))
A58: Notes: ρ-after values for Table 2 rows are back-solved to reproduce the paper’s published R-after column (the source paper does not report a per-cohort ρ-after independently) — treat as illustrative post-improvement resilience. Table 3 rows use the paper’s explicit ρ 0.20 → 0.65 pathway for all aetiologies. C is set to 5 (Severe, BCLC C–D) as an illustrative default for every published-cohort row — the source tables do not specify stage at detection per cohort; edit C to reflect your own population’s typical presentation. Do not edit column K (auto-converted from column J). Rows 17–18 (Patients A and B) reproduce the within-tier EAL walk-through: both sit in the Moderate R-tier, but EAL and Priority rank Patient B first — same tier, more to lose. ρ after equals ρ now for those two rows because the example illustrates one point in time, so Δ risk reads 0% by construction. EAL is rounded to 3 decimals and Priority ranks on that rounded value, as in RMTI-Py; ties on EAL are broken by row order, so every priority number is unique within its tier. Per-capita is EAL ÷ N × 1,000,000; E-log uses the Reference-sheet bounds (100 to 5,000,000) and is advisory only — it never enters R, tier or EAL. Improvement efficiency (IEI) = Δ risk ÷ (1 − ρ after); above 1 means the improvement removes more risk than the exposure it leaves behind.
A66: Decision-support illustration; not validated for clinical use. Posture text is a surveillance-programme reading, not a treatment recommendation.

Sheet Trajectory
A1: Trajectory — time-indexed V(t) and ρ(t) (experimental extension, not in the paper)
A2: Warm cells with blue text are inputs; grey cells calculate. One row per six-monthly surveillance cycle, filled in order from t = 0; leave unused trailing rows blank. Both example patients are SYNTHETIC. Research prototype: not validated, not for patient-care decisions.
A4: Model parameters (shared by both blocks)
A5: v_lo — V at AL = 0 | B5: 0.35 | C5: ALBI grade-1 anchor (see ALBI → Vulnerability sheet).
A6: v_hi — V at AL = AL_max | B6: 0.85 | C6: ALBI grade-3 anchor.
A7: AL_max | B7: 6 | C7: Top of the six-biomarker allostatic-load composite (Abad et al. 2026). Use 13 for the Li et al. version.
A8: α — level gain | B8: 0.41 | C8: Steady-state Kalman gain for noise settings q_level 0.05, q_slope 0.01, r_obs 0.8. Uncalibrated.
A9: β — slope gain | B9: 0.09 | C9: Steady-state Kalman slope gain, same settings. Uncalibrated.
A10: κ·H — look-ahead (cycles) | B10: 1 | C10: Weight on the slope in V*(t). Uncalibrated; the synthetic comparison in the PDF used 2.0.
A11: λ — adherence → ρ | B11: 1 | C11: ρ(t) = ρ(t−1) + λ·ΔAdherence. Placeholder chosen so the examples reproduce the draft. Must be estimated from real serial data; do NOT calibrate it on the back-solved ρ-after values in the RMTI Calculator.
A12: ρ ceiling | B12: 0.95 | C12: Modeling ceiling (core rejects ρ ≥ 1).
A13: Filter on (1) / off (0) | B13: 1 | C13: 0 = use the observed AL directly (draft Eq. 4, memoryless). 1 = use filtered level + κ·H × slope.
A15: Synthetic example T-A — AL falling, adherence rising
A16: L — likelihood (from a validated score) | B16: 0.3
A17: E — exposure | B17: 0.65
A18: C — consequence (1–5), shown for EAL only | B18: 3
A19: ρ at t = 0 | B19: 0.2
A21: Cycle t | B21: AL observed (0–AL_max) | C21: Adherence (0–1) | D21: AL level (filtered) | E21: AL slope / cycle | F21: V*(t) | G21: ρ(t) | H21: R(t) | I21: Tier | J21: ΔR vs previous | K21: Surveillance posture
A22: 0 | B22: 2 | C22: 0.4 | D22: =IF(AND($B22="",$C22=""),"",$B22) -> 2 | E22: =IF(AND($B22="",$C22=""),"",0) -> 0 | F22: =IF(AND($B22="",$C22=""),"",$B$5+($B$6-$B$5)*MAX(0,MIN($B$7,IF($B$13=1,$D22+$B$10*$E22,IF($B22="",$D22,$B22))))/$B$7) -> 0.51666667 | G22: =IF(AND($B22="",$C22=""),"",$B$19) -> 0.2 | H22: =IF(AND($B22="",$C22=""),"",ROUND($B$16*$B$17*$F22*(1-$G22),12)) -> 0.0806 | I22: =IF(AND($B22="",$C22=""),"",INDEX(Reference!$B$11:$B$15,MATCH($H22,Reference!$C$11:$C$15,1))) -> 2 · Moderate | J22: ="" | K22: =IF(AND($B22="",$C22=""),"",INDEX(Reference!$D$11:$D$15,MATCH($H22,Reference!$C$11:$C$15,1))) -> Usual-care biannual surveillance appropriate; confirm adherence and recall
A23: 1 | B23: 1 | C23: 0.55 | D23: =IF(AND($B23="",$C23=""),"",IF($B23="",($D22+$E22),($D22+$E22)+$B$8*($B23-($D22+$E22)))) -> 1.59 | E23: =IF(AND($B23="",$C23=""),"",IF($B23="",$E22,$E22+$B$9*($B23-($D22+$E22)))) -> -0.09 | F23: =IF(AND($B23="",$C23=""),"",$B$5+($B$6-$B$5)*MAX(0,MIN($B$7,IF($B$13=1,$D23+$B$10*$E23,IF($B23="",$D23,$B23))))/$B$7) -> 0.475 | G23: =IF(AND($B23="",$C23=""),"",IF($C23="",$G22,MIN($B$12,MAX(0,$G22+$B$11*($C23-$C22))))) -> 0.35 | H23: =IF(AND($B23="",$C23=""),"",ROUND($B$16*$B$17*$F23*(1-$G23),12)) -> 0.06020625 | I23: =IF(AND($B23="",$C23=""),"",INDEX(Reference!$B$11:$B$15,MATCH($H23,Reference!$C$11:$C$15,1))) -> 2 · Moderate | J23: =IF(AND($B23="",$C23=""),"",$H23-$H22) -> -0.02039375 | K23: =IF(AND($B23="",$C23=""),"",INDEX(Reference!$D$11:$D$15,MATCH($H23,Reference!$C$11:$C$15,1))) -> Usual-care biannual surveillance appropriate; confirm adherence and recall
A24: 2 | B24: 1 | C24: 0.7 | D24: =IF(AND($B24="",$C24=""),"",IF($B24="",($D23+$E23),($D23+$E23)+$B$8*($B24-($D23+$E23)))) -> 1.295 | E24: =IF(AND($B24="",$C24=""),"",IF($B24="",$E23,$E23+$B$9*($B24-($D23+$E23)))) -> -0.135 | F24: =IF(AND($B24="",$C24=""),"",$B$5+($B$6-$B$5)*MAX(0,MIN($B$7,IF($B$13=1,$D24+$B$10*$E24,IF($B24="",$D24,$B24))))/$B$7) -> 0.44666667 | G24: =IF(AND($B24="",$C24=""),"",IF($C24="",$G23,MIN($B$12,MAX(0,$G23+$B$11*($C24-$C23))))) -> 0.5 | H24: =IF(AND($B24="",$C24=""),"",ROUND($B$16*$B$17*$F24*(1-$G24),12)) -> 0.04355 | I24: =IF(AND($B24="",$C24=""),"",INDEX(Reference!$B$11:$B$15,MATCH($H24,Reference!$C$11:$C$15,1))) -> 1 · Low | J24: =IF(AND($B24="",$C24=""),"",$H24-$H23) -> -0.01665625 | K24: =IF(AND($B24="",$C24=""),"",INDEX(Reference!$D$11:$D$15,MATCH($H24,Reference!$C$11:$C$15,1))) -> Monitor; usual-care biannual surveillance appropriate
A25: 3 | B25: 0 | C25: 0.75 | D25: =IF(AND($B25="",$C25=""),"",IF($B25="",($D24+$E24),($D24+$E24)+$B$8*($B25-($D24+$E24)))) -> 0.6844 | E25: =IF(AND($B25="",$C25=""),"",IF($B25="",$E24,$E24+$B$9*($B25-($D24+$E24)))) -> -0.2394 | F25: =IF(AND($B25="",$C25=""),"",$B$5+($B$6-$B$5)*MAX(0,MIN($B$7,IF($B$13=1,$D25+$B$10*$E25,IF($B25="",$D25,$B25))))/$B$7) -> 0.38708333 | G25: =IF(AND($B25="",$C25=""),"",IF($C25="",$G24,MIN($B$12,MAX(0,$G24+$B$11*($C25-$C24))))) -> 0.55 | H25: =IF(AND($B25="",$C25=""),"",ROUND($B$16*$B$17*$F25*(1-$G25),12)) -> 0.033966562 | I25: =IF(AND($B25="",$C25=""),"",INDEX(Reference!$B$11:$B$15,MATCH($H25,Reference!$C$11:$C$15,1))) -> 1 · Low | J25: =IF(AND($B25="",$C25=""),"",$H25-$H24) -> -0.0095834375 | K25: =IF(AND($B25="",$C25=""),"",INDEX(Reference!$D$11:$D$15,MATCH($H25,Reference!$C$11:$C$15,1))) -> Monitor; usual-care biannual surveillance appropriate
A26: 4 | D26: =IF(AND($B26="",$C26=""),"",IF($B26="",($D25+$E25),($D25+$E25)+$B$8*($B26-($D25+$E25)))) | E26: =IF(AND($B26="",$C26=""),"",IF($B26="",$E25,$E25+$B$9*($B26-($D25+$E25)))) | F26: =IF(AND($B26="",$C26=""),"",$B$5+($B$6-$B$5)*MAX(0,MIN($B$7,IF($B$13=1,$D26+$B$10*$E26,IF($B26="",$D26,$B26))))/$B$7) | G26: =IF(AND($B26="",$C26=""),"",IF($C26="",$G25,MIN($B$12,MAX(0,$G25+$B$11*($C26-$C25))))) | H26: =IF(AND($B26="",$C26=""),"",ROUND($B$16*$B$17*$F26*(1-$G26),12)) | I26: =IF(AND($B26="",$C26=""),"",INDEX(Reference!$B$11:$B$15,MATCH($H26,Reference!$C$11:$C$15,1))) | J26: =IF(AND($B26="",$C26=""),"",$H26-$H25) | K26: =IF(AND($B26="",$C26=""),"",INDEX(Reference!$D$11:$D$15,MATCH($H26,Reference!$C$11:$C$15,1)))
A27: 5 | D27: =IF(AND($B27="",$C27=""),"",IF($B27="",($D26+$E26),($D26+$E26)+$B$8*($B27-($D26+$E26)))) | E27: =IF(AND($B27="",$C27=""),"",IF($B27="",$E26,$E26+$B$9*($B27-($D26+$E26)))) | F27: =IF(AND($B27="",$C27=""),"",$B$5+($B$6-$B$5)*MAX(0,MIN($B$7,IF($B$13=1,$D27+$B$10*$E27,IF($B27="",$D27,$B27))))/$B$7) | G27: =IF(AND($B27="",$C27=""),"",IF($C27="",$G26,MIN($B$12,MAX(0,$G26+$B$11*($C27-$C26))))) | H27: =IF(AND($B27="",$C27=""),"",ROUND($B$16*$B$17*$F27*(1-$G27),12)) | I27: =IF(AND($B27="",$C27=""),"",INDEX(Reference!$B$11:$B$15,MATCH($H27,Reference!$C$11:$C$15,1))) | J27: =IF(AND($B27="",$C27=""),"",$H27-$H26) | K27: =IF(AND($B27="",$C27=""),"",INDEX(Reference!$D$11:$D$15,MATCH($H27,Reference!$C$11:$C$15,1)))
A28: 6 | D28: =IF(AND($B28="",$C28=""),"",IF($B28="",($D27+$E27),($D27+$E27)+$B$8*($B28-($D27+$E27)))) | E28: =IF(AND($B28="",$C28=""),"",IF($B28="",$E27,$E27+$B$9*($B28-($D27+$E27)))) | F28: =IF(AND($B28="",$C28=""),"",$B$5+($B$6-$B$5)*MAX(0,MIN($B$7,IF($B$13=1,$D28+$B$10*$E28,IF($B28="",$D28,$B28))))/$B$7) | G28: =IF(AND($B28="",$C28=""),"",IF($C28="",$G27,MIN($B$12,MAX(0,$G27+$B$11*($C28-$C27))))) | H28: =IF(AND($B28="",$C28=""),"",ROUND($B$16*$B$17*$F28*(1-$G28),12)) | I28: =IF(AND($B28="",$C28=""),"",INDEX(Reference!$B$11:$B$15,MATCH($H28,Reference!$C$11:$C$15,1))) | J28: =IF(AND($B28="",$C28=""),"",$H28-$H27) | K28: =IF(AND($B28="",$C28=""),"",INDEX(Reference!$D$11:$D$15,MATCH($H28,Reference!$C$11:$C$15,1)))
A29: 7 | D29: =IF(AND($B29="",$C29=""),"",IF($B29="",($D28+$E28),($D28+$E28)+$B$8*($B29-($D28+$E28)))) | E29: =IF(AND($B29="",$C29=""),"",IF($B29="",$E28,$E28+$B$9*($B29-($D28+$E28)))) | F29: =IF(AND($B29="",$C29=""),"",$B$5+($B$6-$B$5)*MAX(0,MIN($B$7,IF($B$13=1,$D29+$B$10*$E29,IF($B29="",$D29,$B29))))/$B$7) | G29: =IF(AND($B29="",$C29=""),"",IF($C29="",$G28,MIN($B$12,MAX(0,$G28+$B$11*($C29-$C28))))) | H29: =IF(AND($B29="",$C29=""),"",ROUND($B$16*$B$17*$F29*(1-$G29),12)) | I29: =IF(AND($B29="",$C29=""),"",INDEX(Reference!$B$11:$B$15,MATCH($H29,Reference!$C$11:$C$15,1))) | J29: =IF(AND($B29="",$C29=""),"",$H29-$H28) | K29: =IF(AND($B29="",$C29=""),"",INDEX(Reference!$D$11:$D$15,MATCH($H29,Reference!$C$11:$C$15,1)))
A31: Synthetic example T-B — AL rising, adherence flat
A32: L — likelihood (from a validated score) | B32: 0.3
A33: E — exposure | B33: 0.65
A34: C — consequence (1–5), shown for EAL only | B34: 3
A35: ρ at t = 0 | B35: 0.2
A37: Cycle t | B37: AL observed (0–AL_max) | C37: Adherence (0–1) | D37: AL level (filtered) | E37: AL slope / cycle | F37: V*(t) | G37: ρ(t) | H37: R(t) | I37: Tier | J37: ΔR vs previous | K37: Surveillance posture
A38: 0 | B38: 2 | C38: 0.4 | D38: =IF(AND($B38="",$C38=""),"",$B38) -> 2 | E38: =IF(AND($B38="",$C38=""),"",0) -> 0 | F38: =IF(AND($B38="",$C38=""),"",$B$5+($B$6-$B$5)*MAX(0,MIN($B$7,IF($B$13=1,$D38+$B$10*$E38,IF($B38="",$D38,$B38))))/$B$7) -> 0.51666667 | G38: =IF(AND($B38="",$C38=""),"",$B$35) -> 0.2 | H38: =IF(AND($B38="",$C38=""),"",ROUND($B$32*$B$33*$F38*(1-$G38),12)) -> 0.0806 | I38: =IF(AND($B38="",$C38=""),"",INDEX(Reference!$B$11:$B$15,MATCH($H38,Reference!$C$11:$C$15,1))) -> 2 · Moderate | J38: ="" | K38: =IF(AND($B38="",$C38=""),"",INDEX(Reference!$D$11:$D$15,MATCH($H38,Reference!$C$11:$C$15,1))) -> Usual-care biannual surveillance appropriate; confirm adherence and recall
A39: 1 | B39: 3 | C39: 0.4 | D39: =IF(AND($B39="",$C39=""),"",IF($B39="",($D38+$E38),($D38+$E38)+$B$8*($B39-($D38+$E38)))) -> 2.41 | E39: =IF(AND($B39="",$C39=""),"",IF($B39="",$E38,$E38+$B$9*($B39-($D38+$E38)))) -> 0.09 | F39: =IF(AND($B39="",$C39=""),"",$B$5+($B$6-$B$5)*MAX(0,MIN($B$7,IF($B$13=1,$D39+$B$10*$E39,IF($B39="",$D39,$B39))))/$B$7) -> 0.55833333 | G39: =IF(AND($B39="",$C39=""),"",IF($C39="",$G38,MIN($B$12,MAX(0,$G38+$B$11*($C39-$C38))))) -> 0.2 | H39: =IF(AND($B39="",$C39=""),"",ROUND($B$32*$B$33*$F39*(1-$G39),12)) -> 0.0871 | I39: =IF(AND($B39="",$C39=""),"",INDEX(Reference!$B$11:$B$15,MATCH($H39,Reference!$C$11:$C$15,1))) -> 2 · Moderate | J39: =IF(AND($B39="",$C39=""),"",$H39-$H38) -> 0.0065 | K39: =IF(AND($B39="",$C39=""),"",INDEX(Reference!$D$11:$D$15,MATCH($H39,Reference!$C$11:$C$15,1))) -> Usual-care biannual surveillance appropriate; confirm adherence and recall
A40: 2 | B40: 4 | C40: 0.35 | D40: =IF(AND($B40="",$C40=""),"",IF($B40="",($D39+$E39),($D39+$E39)+$B$8*($B40-($D39+$E39)))) -> 3.115 | E40: =IF(AND($B40="",$C40=""),"",IF($B40="",$E39,$E39+$B$9*($B40-($D39+$E39)))) -> 0.225 | F40: =IF(AND($B40="",$C40=""),"",$B$5+($B$6-$B$5)*MAX(0,MIN($B$7,IF($B$13=1,$D40+$B$10*$E40,IF($B40="",$D40,$B40))))/$B$7) -> 0.62833333 | G40: =IF(AND($B40="",$C40=""),"",IF($C40="",$G39,MIN($B$12,MAX(0,$G39+$B$11*($C40-$C39))))) -> 0.15 | H40: =IF(AND($B40="",$C40=""),"",ROUND($B$32*$B$33*$F40*(1-$G40),12)) -> 0.10414625 | I40: =IF(AND($B40="",$C40=""),"",INDEX(Reference!$B$11:$B$15,MATCH($H40,Reference!$C$11:$C$15,1))) -> 2 · Moderate | J40: =IF(AND($B40="",$C40=""),"",$H40-$H39) -> 0.01704625 | K40: =IF(AND($B40="",$C40=""),"",INDEX(Reference!$D$11:$D$15,MATCH($H40,Reference!$C$11:$C$15,1))) -> Usual-care biannual surveillance appropriate; confirm adherence and recall
A41: 3 | B41: 5 | C41: 0.35 | D41: =IF(AND($B41="",$C41=""),"",IF($B41="",($D40+$E40),($D40+$E40)+$B$8*($B41-($D40+$E40)))) -> 4.0206 | E41: =IF(AND($B41="",$C41=""),"",IF($B41="",$E40,$E40+$B$9*($B41-($D40+$E40)))) -> 0.3744 | F41: =IF(AND($B41="",$C41=""),"",$B$5+($B$6-$B$5)*MAX(0,MIN($B$7,IF($B$13=1,$D41+$B$10*$E41,IF($B41="",$D41,$B41))))/$B$7) -> 0.71625 | G41: =IF(AND($B41="",$C41=""),"",IF($C41="",$G40,MIN($B$12,MAX(0,$G40+$B$11*($C41-$C40))))) -> 0.15 | H41: =IF(AND($B41="",$C41=""),"",ROUND($B$32*$B$33*$F41*(1-$G41),12)) -> 0.11871844 | I41: =IF(AND($B41="",$C41=""),"",INDEX(Reference!$B$11:$B$15,MATCH($H41,Reference!$C$11:$C$15,1))) -> 2 · Moderate | J41: =IF(AND($B41="",$C41=""),"",$H41-$H40) -> 0.014572188 | K41: =IF(AND($B41="",$C41=""),"",INDEX(Reference!$D$11:$D$15,MATCH($H41,Reference!$C$11:$C$15,1))) -> Usual-care biannual surveillance appropriate; confirm adherence and recall
