Workbook

Sheet Cover
B2: ENVR E-241 · Risk by Design
B4: RMTI Calculator · v2.3.0 time-indexed
B6: Risk Mechanism Theory Index — a single, decision-ready score to assess, quantify and treat urban climate risk.
B9: The model at a glance
B10: Core score | C10: R = Σ w·L·E·V·(1−ρ) — exposure & vulnerability raise R; resilience lowers it
B11: Severity layer | C11: EAL = Σ L·C·(1−ρ) — carries likelihood × consequence into expected loss
B12: Exposure from N | C12: E = [log₁₀(N) − log₁₀(Nₘᵢₙ)] / [log₁₀(Nₘₐₓ) − log₁₀(Nₘᵢₙ)], anchors Nₘᵢₙ=10, Nₘₐₓ=20,000,000
B13: Per-capita lens | C13: rate = EAL ÷ population — reported alongside R for equity
B14: Fixed tiers | C14: 1 Low <0.05 · 2 Moderate 0.05–0.15 · 3 High 0.15–0.35 · 4 Severe 0.35–0.60 · 5 Critical ≥0.60
B16: What's inside
B17: • How to Use — step-by-step input guide and a worked walk-through (Lilongwe).
B18: • RMTI Calculator — all cases in one continuous, auto-calculating table; add your own cities at the foot.
B19: • Reference — fixed tiers, consequence scale, exposure anchors and the Table 9.4 indicator backbone.
B20: • Trajectory — experimental time-indexed V(t) and ρ(t) per annual review cycle, with two synthetic examples (not validated).
B21: © 2025–2026 Cesar Marolla. The Risk Mechanism Theory Index (RMTI) was developed for ENVR E-241 Risk by Design. Licensed under the Apache License, Version 2.0 (see LICENSE and NOTICE in the repository). Copyright 2026 Cesar Marolla (ORCID 0000-0001-8498-7380). Provided "as is", without warranty.

Sheet How to Use
B1: ENVR E-241 · Risk by Design
B2: How to use the RMTI Calculator
B3: Type into the warm-shaded (blue-text) cells only. Everything else recalculates automatically.
B5: Step 1 — Enter the inputs (warm cells)
B6: Population N | C6: Beneficiaries or people in the hazard footprint. Drives the log-exposure helper column E (log).
B7: L · Likelihood | C7: Annual probability the hazard materially strikes the asset, on 0–1 (1–5 band midpoints).
B8: E · Exposure (used) | C8: Share of people/assets in harm's way, 0–1. Tip: copy the E (log) helper value, or enter your own rubric value.
B9: V · Vulnerability | C9: Sensitivity given adaptive capacity (housing, utilities, services), 0–1.
B10: ρ now / ρ after | C10: Resilience (coping capacity) before and after the adaptation package, 0–1. Enters as (1−ρ).
B11: C · Consequence (1–5) | C11: Severity of a failure: 1 Insignificant · 2 Minor · 3 Moderate · 4 Major · 5 Severe. Maps to 0–1 for EAL.
B13: Step 2 — Read the results (auto-calculated)
B14: Inherent risk | C14: L · E · V — risk before resilience is applied.
B15: R now / R after | C15: Inherent × (1−ρ). The decision score, bounded 0–1.
B16: Tier | C16: Maps R to the fixed 1–5 band — same thresholds for every city, every year.
B17: Δ risk % | C17: Percentage cut in R from the resilience investment.
B18: EAL index | C18: L · C · (1−ρ) — expected-loss index that carries severity through.
B19: Per-capita | C19: EAL ÷ population (shown per 1,000,000 residents) — the equity lens.
B21: Step 3 — Add your own city
B22: Type a new city into the first empty row beneath the populated ones. Formulas in the grey result columns are already in place and will calculate as soon as you enter N, L, E, V and ρ. Leave ρ after blank if you are only scoring the current state.
B24: Worked walk-through — Lilongwe, Malawi
B25: • N = 1,100,000 → E (log) = (log₁₀(1,100,000) − 1) / (log₁₀(20,000,000) − 1) = 5.0414 / 6.3010 = 0.80
B26: • Inherent = L · E · V = 0.875 · 0.80 · 0.80 = 0.56
B27: • R now = 0.56 · (1 − 0.25) = 0.42 → Tier 4 · Severe (resilience shields only 25% of inherent risk)
B28: • R after = 0.56 · (1 − 0.48) = 0.29 → Tier 3 · High (target pathway ρ 0.43–0.53 by 2027–2030)
B30: © 2025–2026 Cesar Marolla. The Risk Mechanism Theory Index (RMTI) was developed for ENVR E-241 Risk by Design. Licensed under the Apache License, Version 2.0 (see LICENSE and NOTICE in the repository). Copyright 2026 Cesar Marolla (ORCID 0000-0001-8498-7380). Provided "as is", without warranty.

Sheet Reference
B1: ENVR E-241 · Risk by Design
B2: Reference tables
B4: Exposure anchors
B5: Nmin | C5: 10 | D5: smallest viable scheme (people)
B6: Nmax | C6: 20000000 | D6: largest metro ceiling (people)
B8: Fixed scoring tiers
B9: Tier | C9: R band | D9: Posture
B10: 1 · Low | C10: R < 0.05 | D10: Monitor; maintain baseline
B11: 2 · Moderate | C11: 0.05 – 0.15 | D11: Low-regret preventive measures
B12: 3 · High | C12: 0.15 – 0.35 | D12: Structured mitigation; fund soon
B13: 4 · Severe | C13: 0.35 – 0.60 | D13: Priority capital; act now
B14: 5 · Critical | C14: R ≥ 0.60 | D14: Immediate, system-level response
B16: Consequence scale (C)
B17: Score | C17: Severity → 0–1 | D17: People affected
B18: 1 · Insignificant | C18: 0.10 | D18: < 50
B19: 2 · Minor | C19: 0.30 | D19: 50 – 500
B20: 3 · Moderate | C20: 0.50 | D20: 500 – 50,000
B21: 4 · Major | C21: 0.75 | D21: 50,000 – 1,000,000
B22: 5 · Severe | C22: 1.00 | D22: > 1,000,000
B24: Table 9.4 — indicator backbone
B25: RMTre → E (raises R) | D25: RMTseen → V (raises R) | F25: RMTrl → ρ (lowers R)
B26: • Natural & man-made disasters; climate change | D26: • Fiscal stability; inequality & wealth distribution | F26: • Risk-management strategy; business continuity
B27: • Health hazards; pandemics; food & water scarcity | D27: • Control of corruption; rule of law; governance | F27: • ICT, energy & urban infrastructure quality
B28: • Accelerated urbanism; population growth | D28: • Environmental pollution; land degradation | F28: • Hospital capacity; health care; water/food security
B29: • Inherent cyber-risk; obsolete ICT | D29: • Poverty indices; GDP per capita; institutions | F29: • Renewable energy; demand rationing; recycling
B31: © 2025–2026 Cesar Marolla. The Risk Mechanism Theory Index (RMTI) was developed for ENVR E-241 Risk by Design. Licensed under the Apache License, Version 2.0 (see LICENSE and NOTICE in the repository). Copyright 2026 Cesar Marolla (ORCID 0000-0001-8498-7380). Provided "as is", without warranty.

Sheet RMTI Calculator
A1: RMTI Calculator — assess · quantify · treat
A2: ENVR E-241 · Risk by Design · Inputs are the warm/blue cells; grey columns auto-calculate. E (log) is derived from N — copy it into E (used) for an audited, population-based score.
L3: ▶ You type here | M3: Auto-calculates | X3: New analysis
A4: City | B4: Country | C4: Set | D4: Hazard (h) | E4: Population N | F4: L | G4: E (log) | H4: E (used) | I4: V | J4: ρ now | K4: ρ after | L4: C (1–5) ← Analyst rubric score (enter 1–5) | M4: C (0–1) ← Auto-converted for R formula | N4: Inherent L·E·V | O4: R now | P4: Tier now | Q4: R after | R4: Tier after | S4: Δ risk | T4: EAL now | U4: EAL after | V4: Per-capita now (/1M) | W4: Priority (in tier) | X4: Per-capita after (/1M) | Y4: Priority after (in tier) | Z4: Investment Efficiency Index (IEI)
A5: Bamako | B5: Mali | C5: Worked example | D5: Drought · flood · heat | E5: 4500000 | F5: 0.8 | G5: =IF($E5="","",MIN(1,MAX(0,(LOG10($E5)-LOG10(Nmin))/(LOG10(Nmax)-LOG10(Nmin))))) -> 0.89718864 | H5: 0.85 | I5: 0.75 | J5: 0.2 | K5: 0.58 | L5: 4 | M5: =IF($L5="","",CHOOSE($L5,0.1,0.3,0.5,0.75,1)) -> 0.75 | N5: =IF(OR($F5="",$H5="",$I5=""),"",$F5*$H5*$I5) -> 0.51 | O5: =IF(OR($N5="",$J5=""),"",$N5*(1-$J5)) -> 0.408 | P5: =IF($O5="","",IF($O5<0.05,"1 · Low",IF($O5<0.15,"2 · Moderate",IF($O5<0.35,"3 · High",IF($O5<0.6,"4 · Severe","5 · Critical"))))) -> 4 · Severe | Q5: =IF(OR($N5="",$K5=""),"",$N5*(1-$K5)) -> 0.2142 | R5: =IF($Q5="","",IF($Q5<0.05,"1 · Low",IF($Q5<0.15,"2 · Moderate",IF($Q5<0.35,"3 · High",IF($Q5<0.6,"4 · Severe","5 · Critical"))))) -> 3 · High | S5: =IF(OR($O5="",$Q5=""),"",($O5-$Q5)/$O5) -> 0.475 | T5: =IF(OR($F5="",$M5="",$J5=""),"",$F5*$M5*(1-$J5)) -> 0.48 | U5: =IF(OR($F5="",$M5="",$K5=""),"",$F5*$M5*(1-$K5)) -> 0.252 | V5: =IF(OR($T5="",$E5=""),"",$T5/$E5*1000000) -> 0.10666667 | W5: =IF($O5="","",COUNTIFS($P$5:$P$17,$P5,$T$5:$T$17,">"&$T5)+1) -> 3 | X5: =IF(OR($U5="",$E5=""),"",$U5/$E5*1000000) -> 0.056 | Y5: =IF(OR($Q5="",$R5=""),"",COUNTIFS($R$5:$R$17,$R5,$U$5:$U$17,">"&$U5)+1) -> 3 | Z5: =IF(OR($S5="",$K5="",1-$K5=0),"",$S5/(1-$K5)) -> 1.1309524
A6: Lagos | B6: Nigeria | C6: Worked example | D6: Coastal & pluvial flood | E6: 16000000 | F6: 0.9 | G6: =IF($E6="","",MIN(1,MAX(0,(LOG10($E6)-LOG10(Nmin))/(LOG10(Nmax)-LOG10(Nmin))))) -> 0.98461997 | H6: 0.65 | I6: 0.8 | J6: 0.2 | K6: 0.55 | L6: 5 | M6: =IF($L6="","",CHOOSE($L6,0.1,0.3,0.5,0.75,1)) -> 1 | N6: =IF(OR($F6="",$H6="",$I6=""),"",$F6*$H6*$I6) -> 0.468 | O6: =IF(OR($N6="",$J6=""),"",$N6*(1-$J6)) -> 0.3744 | P6: =IF($O6="","",IF($O6<0.05,"1 · Low",IF($O6<0.15,"2 · Moderate",IF($O6<0.35,"3 · High",IF($O6<0.6,"4 · Severe","5 · Critical"))))) -> 4 · Severe | Q6: =IF(OR($N6="",$K6=""),"",$N6*(1-$K6)) -> 0.2106 | R6: =IF($Q6="","",IF($Q6<0.05,"1 · Low",IF($Q6<0.15,"2 · Moderate",IF($Q6<0.35,"3 · High",IF($Q6<0.6,"4 · Severe","5 · Critical"))))) -> 3 · High | S6: =IF(OR($O6="",$Q6=""),"",($O6-$Q6)/$O6) -> 0.4375 | T6: =IF(OR($F6="",$M6="",$J6=""),"",$F6*$M6*(1-$J6)) -> 0.72 | U6: =IF(OR($F6="",$M6="",$K6=""),"",$F6*$M6*(1-$K6)) -> 0.405 | V6: =IF(OR($T6="",$E6=""),"",$T6/$E6*1000000) -> 0.045 | W6: =IF($O6="","",COUNTIFS($P$5:$P$17,$P6,$T$5:$T$17,">"&$T6)+1) -> 1 | X6: =IF(OR($U6="",$E6=""),"",$U6/$E6*1000000) -> 0.0253125 | Y6: =IF(OR($Q6="",$R6=""),"",COUNTIFS($R$5:$R$17,$R6,$U$5:$U$17,">"&$U6)+1) -> 1 | Z6: =IF(OR($S6="",$K6="",1-$K6=0),"",$S6/(1-$K6)) -> 0.97222222
A7: Lilongwe ★ | B7: Malawi | C7: Worked example | D7: Pluvial · river flood | E7: 1100000 | F7: 0.875 | G7: =IF($E7="","",MIN(1,MAX(0,(LOG10($E7)-LOG10(Nmin))/(LOG10(Nmax)-LOG10(Nmin))))) -> 0.80009025 | H7: 0.8 | I7: 0.8 | J7: 0.25 | K7: 0.48 | L7: 4 | M7: =IF($L7="","",CHOOSE($L7,0.1,0.3,0.5,0.75,1)) -> 0.75 | N7: =IF(OR($F7="",$H7="",$I7=""),"",$F7*$H7*$I7) -> 0.56 | O7: =IF(OR($N7="",$J7=""),"",$N7*(1-$J7)) -> 0.42 | P7: =IF($O7="","",IF($O7<0.05,"1 · Low",IF($O7<0.15,"2 · Moderate",IF($O7<0.35,"3 · High",IF($O7<0.6,"4 · Severe","5 · Critical"))))) -> 4 · Severe | Q7: =IF(OR($N7="",$K7=""),"",$N7*(1-$K7)) -> 0.2912 | R7: =IF($Q7="","",IF($Q7<0.05,"1 · Low",IF($Q7<0.15,"2 · Moderate",IF($Q7<0.35,"3 · High",IF($Q7<0.6,"4 · Severe","5 · Critical"))))) -> 3 · High | S7: =IF(OR($O7="",$Q7=""),"",($O7-$Q7)/$O7) -> 0.30666667 | T7: =IF(OR($F7="",$M7="",$J7=""),"",$F7*$M7*(1-$J7)) -> 0.4921875 | U7: =IF(OR($F7="",$M7="",$K7=""),"",$F7*$M7*(1-$K7)) -> 0.34125 | V7: =IF(OR($T7="",$E7=""),"",$T7/$E7*1000000) -> 0.44744318 | W7: =IF($O7="","",COUNTIFS($P$5:$P$17,$P7,$T$5:$T$17,">"&$T7)+1) -> 2 | X7: =IF(OR($U7="",$E7=""),"",$U7/$E7*1000000) -> 0.31022727 | Y7: =IF(OR($Q7="",$R7=""),"",COUNTIFS($R$5:$R$17,$R7,$U$5:$U$17,">"&$U7)+1) -> 2 | Z7: =IF(OR($S7="",$K7="",1-$K7=0),"",$S7/(1-$K7)) -> 0.58974359
A8: Nairobi | B8: Kenya | C8: Comparator | D8: Pluvial flood | E8: 4700000 | F8: 0.9 | G8: =IF($E8="","",MIN(1,MAX(0,(LOG10($E8)-LOG10(Nmin))/(LOG10(Nmax)-LOG10(Nmin))))) -> 0.90018582 | H8: 0.88 | I8: 0.55 | J8: 0.55 | K8: 0.65 | L8: 4 | M8: =IF($L8="","",CHOOSE($L8,0.1,0.3,0.5,0.75,1)) -> 0.75 | N8: =IF(OR($F8="",$H8="",$I8=""),"",$F8*$H8*$I8) -> 0.4356 | O8: =IF(OR($N8="",$J8=""),"",$N8*(1-$J8)) -> 0.19602 | P8: =IF($O8="","",IF($O8<0.05,"1 · Low",IF($O8<0.15,"2 · Moderate",IF($O8<0.35,"3 · High",IF($O8<0.6,"4 · Severe","5 · Critical"))))) -> 3 · High | Q8: =IF(OR($N8="",$K8=""),"",$N8*(1-$K8)) -> 0.15246 | R8: =IF($Q8="","",IF($Q8<0.05,"1 · Low",IF($Q8<0.15,"2 · Moderate",IF($Q8<0.35,"3 · High",IF($Q8<0.6,"4 · Severe","5 · Critical"))))) -> 3 · High | S8: =IF(OR($O8="",$Q8=""),"",($O8-$Q8)/$O8) -> 0.22222222 | T8: =IF(OR($F8="",$M8="",$J8=""),"",$F8*$M8*(1-$J8)) -> 0.30375 | U8: =IF(OR($F8="",$M8="",$K8=""),"",$F8*$M8*(1-$K8)) -> 0.23625 | V8: =IF(OR($T8="",$E8=""),"",$T8/$E8*1000000) -> 0.06462766 | W8: =IF($O8="","",COUNTIFS($P$5:$P$17,$P8,$T$5:$T$17,">"&$T8)+1) -> 1 | X8: =IF(OR($U8="",$E8=""),"",$U8/$E8*1000000) -> 0.050265957 | Y8: =IF(OR($Q8="",$R8=""),"",COUNTIFS($R$5:$R$17,$R8,$U$5:$U$17,">"&$U8)+1) -> 4 | Z8: =IF(OR($S8="",$K8="",1-$K8=0),"",$S8/(1-$K8)) -> 0.63492063
A9: Dar es Salaam | B9: Tanzania | C9: Comparator | D9: Coastal flood | E9: 7400000 | F9: 0.85 | G9: =IF($E9="","",MIN(1,MAX(0,(LOG10($E9)-LOG10(Nmin))/(LOG10(Nmax)-LOG10(Nmin))))) -> 0.93147179 | H9: 0.93 | I9: 0.78 | J9: 0.55 | K9: 0.7 | L9: 4 | M9: =IF($L9="","",CHOOSE($L9,0.1,0.3,0.5,0.75,1)) -> 0.75 | N9: =IF(OR($F9="",$H9="",$I9=""),"",$F9*$H9*$I9) -> 0.61659 | O9: =IF(OR($N9="",$J9=""),"",$N9*(1-$J9)) -> 0.2774655 | P9: =IF($O9="","",IF($O9<0.05,"1 · Low",IF($O9<0.15,"2 · Moderate",IF($O9<0.35,"3 · High",IF($O9<0.6,"4 · Severe","5 · Critical"))))) -> 3 · High | Q9: =IF(OR($N9="",$K9=""),"",$N9*(1-$K9)) -> 0.184977 | R9: =IF($Q9="","",IF($Q9<0.05,"1 · Low",IF($Q9<0.15,"2 · Moderate",IF($Q9<0.35,"3 · High",IF($Q9<0.6,"4 · Severe","5 · Critical"))))) -> 3 · High | S9: =IF(OR($O9="",$Q9=""),"",($O9-$Q9)/$O9) -> 0.33333333 | T9: =IF(OR($F9="",$M9="",$J9=""),"",$F9*$M9*(1-$J9)) -> 0.286875 | U9: =IF(OR($F9="",$M9="",$K9=""),"",$F9*$M9*(1-$K9)) -> 0.19125 | V9: =IF(OR($T9="",$E9=""),"",$T9/$E9*1000000) -> 0.038766892 | W9: =IF($O9="","",COUNTIFS($P$5:$P$17,$P9,$T$5:$T$17,">"&$T9)+1) -> 2 | X9: =IF(OR($U9="",$E9=""),"",$U9/$E9*1000000) -> 0.025844595 | Y9: =IF(OR($Q9="",$R9=""),"",COUNTIFS($R$5:$R$17,$R9,$U$5:$U$17,">"&$U9)+1) -> 5 | Z9: =IF(OR($S9="",$K9="",1-$K9=0),"",$S9/(1-$K9)) -> 1.1111111
A10: Lusaka | B10: Zambia | C10: Comparator | D10: Flood · cholera | E10: 3360000 | F10: 0.8 | G10: =IF($E10="","",MIN(1,MAX(0,(LOG10($E10)-LOG10(Nmin))/(LOG10(Nmax)-LOG10(Nmin))))) -> 0.87705332 | H10: 0.85 | I10: 0.72 | J10: 0.45 | K10: 0.6 | L10: 3 | M10: =IF($L10="","",CHOOSE($L10,0.1,0.3,0.5,0.75,1)) -> 0.5 | N10: =IF(OR($F10="",$H10="",$I10=""),"",$F10*$H10*$I10) -> 0.4896 | O10: =IF(OR($N10="",$J10=""),"",$N10*(1-$J10)) -> 0.26928 | P10: =IF($O10="","",IF($O10<0.05,"1 · Low",IF($O10<0.15,"2 · Moderate",IF($O10<0.35,"3 · High",IF($O10<0.6,"4 · Severe","5 · Critical"))))) -> 3 · High | Q10: =IF(OR($N10="",$K10=""),"",$N10*(1-$K10)) -> 0.19584 | R10: =IF($Q10="","",IF($Q10<0.05,"1 · Low",IF($Q10<0.15,"2 · Moderate",IF($Q10<0.35,"3 · High",IF($Q10<0.6,"4 · Severe","5 · Critical"))))) -> 3 · High | S10: =IF(OR($O10="",$Q10=""),"",($O10-$Q10)/$O10) -> 0.27272727 | T10: =IF(OR($F10="",$M10="",$J10=""),"",$F10*$M10*(1-$J10)) -> 0.22 | U10: =IF(OR($F10="",$M10="",$K10=""),"",$F10*$M10*(1-$K10)) -> 0.16 | V10: =IF(OR($T10="",$E10=""),"",$T10/$E10*1000000) -> 0.06547619 | W10: =IF($O10="","",COUNTIFS($P$5:$P$17,$P10,$T$5:$T$17,">"&$T10)+1) -> 4 | X10: =IF(OR($U10="",$E10=""),"",$U10/$E10*1000000) -> 0.047619048 | Y10: =IF(OR($Q10="",$R10=""),"",COUNTIFS($R$5:$R$17,$R10,$U$5:$U$17,">"&$U10)+1) -> 6 | Z10: =IF(OR($S10="",$K10="",1-$K10=0),"",$S10/(1-$K10)) -> 0.68181818
A11: Pacific Palisades | B11: USA | C11: 2025 case study | D11: Wildfire (WUI) — Palisades Fire, Jan 2025 | E11: 21300 | F11: 0.4 | G11: =IF($E11="","",MIN(1,MAX(0,(LOG10($E11)-LOG10(Nmin))/(LOG10(Nmax)-LOG10(Nmin))))) -> 0.52822786 | H11: 0.9 | I11: 0.4 | J11: 0.2 | K11: 0.35 | L11: 4 | M11: =IF($L11="","",CHOOSE($L11,0.1,0.3,0.5,0.75,1)) -> 0.75 | N11: =IF(OR($F11="",$H11="",$I11=""),"",$F11*$H11*$I11) -> 0.144 | O11: =IF(OR($N11="",$J11=""),"",$N11*(1-$J11)) -> 0.1152 | P11: =IF($O11="","",IF($O11<0.05,"1 · Low",IF($O11<0.15,"2 · Moderate",IF($O11<0.35,"3 · High",IF($O11<0.6,"4 · Severe","5 · Critical"))))) -> 2 · Moderate | Q11: =IF(OR($N11="",$K11=""),"",$N11*(1-$K11)) -> 0.0936 | R11: =IF($Q11="","",IF($Q11<0.05,"1 · Low",IF($Q11<0.15,"2 · Moderate",IF($Q11<0.35,"3 · High",IF($Q11<0.6,"4 · Severe","5 · Critical"))))) -> 2 · Moderate | S11: =IF(OR($O11="",$Q11=""),"",($O11-$Q11)/$O11) -> 0.1875 | T11: =IF(OR($F11="",$M11="",$J11=""),"",$F11*$M11*(1-$J11)) -> 0.24 | U11: =IF(OR($F11="",$M11="",$K11=""),"",$F11*$M11*(1-$K11)) -> 0.195 | V11: =IF(OR($T11="",$E11=""),"",$T11/$E11*1000000) -> 11.267606 | W11: =IF($O11="","",COUNTIFS($P$5:$P$17,$P11,$T$5:$T$17,">"&$T11)+1) -> 1 | X11: =IF(OR($U11="",$E11=""),"",$U11/$E11*1000000) -> 9.1549296 | Y11: =IF(OR($Q11="",$R11=""),"",COUNTIFS($R$5:$R$17,$R11,$U$5:$U$17,">"&$U11)+1) -> 1 | Z11: =IF(OR($S11="",$K11="",1-$K11=0),"",$S11/(1-$K11)) -> 0.28846154
A12: Altadena | B12: USA | C12: 2025 case study | D12: Wildfire (WUI) — Eaton Fire, Jan 2025 | E12: 23000 | F12: 0.4 | G12: =IF($E12="","",MIN(1,MAX(0,(LOG10($E12)-LOG10(Nmin))/(LOG10(Nmax)-LOG10(Nmin))))) -> 0.53352037 | H12: 0.8 | I12: 0.6 | J12: 0.2 | K12: 0.35 | L12: 4 | M12: =IF($L12="","",CHOOSE($L12,0.1,0.3,0.5,0.75,1)) -> 0.75 | N12: =IF(OR($F12="",$H12="",$I12=""),"",$F12*$H12*$I12) -> 0.192 | O12: =IF(OR($N12="",$J12=""),"",$N12*(1-$J12)) -> 0.1536 | P12: =IF($O12="","",IF($O12<0.05,"1 · Low",IF($O12<0.15,"2 · Moderate",IF($O12<0.35,"3 · High",IF($O12<0.6,"4 · Severe","5 · Critical"))))) -> 3 · High | Q12: =IF(OR($N12="",$K12=""),"",$N12*(1-$K12)) -> 0.1248 | R12: =IF($Q12="","",IF($Q12<0.05,"1 · Low",IF($Q12<0.15,"2 · Moderate",IF($Q12<0.35,"3 · High",IF($Q12<0.6,"4 · Severe","5 · Critical"))))) -> 2 · Moderate | S12: =IF(OR($O12="",$Q12=""),"",($O12-$Q12)/$O12) -> 0.1875 | T12: =IF(OR($F12="",$M12="",$J12=""),"",$F12*$M12*(1-$J12)) -> 0.24 | U12: =IF(OR($F12="",$M12="",$K12=""),"",$F12*$M12*(1-$K12)) -> 0.195 | V12: =IF(OR($T12="",$E12=""),"",$T12/$E12*1000000) -> 10.434783 | W12: =IF($O12="","",COUNTIFS($P$5:$P$17,$P12,$T$5:$T$17,">"&$T12)+1) -> 3 | X12: =IF(OR($U12="",$E12=""),"",$U12/$E12*1000000) -> 8.4782609 | Y12: =IF(OR($Q12="",$R12=""),"",COUNTIFS($R$5:$R$17,$R12,$U$5:$U$17,">"&$U12)+1) -> 1 | Z12: =IF(OR($S12="",$K12="",1-$K12=0),"",$S12/(1-$K12)) -> 0.28846154
G13: =IF($E13="","",MIN(1,MAX(0,(LOG10($E13)-LOG10(Nmin))/(LOG10(Nmax)-LOG10(Nmin))))) | M13: =IF($L13="","",CHOOSE($L13,0.1,0.3,0.5,0.75,1)) | N13: =IF(OR($F13="",$H13="",$I13=""),"",$F13*$H13*$I13) | O13: =IF(OR($N13="",$J13=""),"",$N13*(1-$J13)) | P13: =IF($O13="","",IF($O13<0.05,"1 · Low",IF($O13<0.15,"2 · Moderate",IF($O13<0.35,"3 · High",IF($O13<0.6,"4 · Severe","5 · Critical"))))) | Q13: =IF(OR($N13="",$K13=""),"",$N13*(1-$K13)) | R13: =IF($Q13="","",IF($Q13<0.05,"1 · Low",IF($Q13<0.15,"2 · Moderate",IF($Q13<0.35,"3 · High",IF($Q13<0.6,"4 · Severe","5 · Critical"))))) | S13: =IF(OR($O13="",$Q13=""),"",($O13-$Q13)/$O13) | T13: =IF(OR($F13="",$M13="",$J13=""),"",$F13*$M13*(1-$J13)) | U13: =IF(OR($F13="",$M13="",$K13=""),"",$F13*$M13*(1-$K13)) | V13: =IF(OR($T13="",$E13=""),"",$T13/$E13*1000000) | W13: =IF($O13="","",COUNTIFS($P$5:$P$17,$P13,$T$5:$T$17,">"&$T13)+1) | X13: =IF(OR($U13="",$E13=""),"",$U13/$E13*1000000) | Y13: =IF(OR($Q13="",$R13=""),"",COUNTIFS($R$5:$R$17,$R13,$U$5:$U$17,">"&$U13)+1) | Z13: =IF(OR($S13="",$K13="",1-$K13=0),"",$S13/(1-$K13))
G14: =IF($E14="","",MIN(1,MAX(0,(LOG10($E14)-LOG10(Nmin))/(LOG10(Nmax)-LOG10(Nmin))))) | M14: =IF($L14="","",CHOOSE($L14,0.1,0.3,0.5,0.75,1)) | N14: =IF(OR($F14="",$H14="",$I14=""),"",$F14*$H14*$I14) | O14: =IF(OR($N14="",$J14=""),"",$N14*(1-$J14)) | P14: =IF($O14="","",IF($O14<0.05,"1 · Low",IF($O14<0.15,"2 · Moderate",IF($O14<0.35,"3 · High",IF($O14<0.6,"4 · Severe","5 · Critical"))))) | Q14: =IF(OR($N14="",$K14=""),"",$N14*(1-$K14)) | R14: =IF($Q14="","",IF($Q14<0.05,"1 · Low",IF($Q14<0.15,"2 · Moderate",IF($Q14<0.35,"3 · High",IF($Q14<0.6,"4 · Severe","5 · Critical"))))) | S14: =IF(OR($O14="",$Q14=""),"",($O14-$Q14)/$O14) | T14: =IF(OR($F14="",$M14="",$J14=""),"",$F14*$M14*(1-$J14)) | U14: =IF(OR($F14="",$M14="",$K14=""),"",$F14*$M14*(1-$K14)) | V14: =IF(OR($T14="",$E14=""),"",$T14/$E14*1000000) | W14: =IF($O14="","",COUNTIFS($P$5:$P$17,$P14,$T$5:$T$17,">"&$T14)+1) | X14: =IF(OR($U14="",$E14=""),"",$U14/$E14*1000000) | Y14: =IF(OR($Q14="",$R14=""),"",COUNTIFS($R$5:$R$17,$R14,$U$5:$U$17,">"&$U14)+1) | Z14: =IF(OR($S14="",$K14="",1-$K14=0),"",$S14/(1-$K14))
G15: =IF($E15="","",MIN(1,MAX(0,(LOG10($E15)-LOG10(Nmin))/(LOG10(Nmax)-LOG10(Nmin))))) | M15: =IF($L15="","",CHOOSE($L15,0.1,0.3,0.5,0.75,1)) | N15: =IF(OR($F15="",$H15="",$I15=""),"",$F15*$H15*$I15) | O15: =IF(OR($N15="",$J15=""),"",$N15*(1-$J15)) | P15: =IF($O15="","",IF($O15<0.05,"1 · Low",IF($O15<0.15,"2 · Moderate",IF($O15<0.35,"3 · High",IF($O15<0.6,"4 · Severe","5 · Critical"))))) | Q15: =IF(OR($N15="",$K15=""),"",$N15*(1-$K15)) | R15: =IF($Q15="","",IF($Q15<0.05,"1 · Low",IF($Q15<0.15,"2 · Moderate",IF($Q15<0.35,"3 · High",IF($Q15<0.6,"4 · Severe","5 · Critical"))))) | S15: =IF(OR($O15="",$Q15=""),"",($O15-$Q15)/$O15) | T15: =IF(OR($F15="",$M15="",$J15=""),"",$F15*$M15*(1-$J15)) | U15: =IF(OR($F15="",$M15="",$K15=""),"",$F15*$M15*(1-$K15)) | V15: =IF(OR($T15="",$E15=""),"",$T15/$E15*1000000) | W15: =IF($O15="","",COUNTIFS($P$5:$P$17,$P15,$T$5:$T$17,">"&$T15)+1) | X15: =IF(OR($U15="",$E15=""),"",$U15/$E15*1000000) | Y15: =IF(OR($Q15="",$R15=""),"",COUNTIFS($R$5:$R$17,$R15,$U$5:$U$17,">"&$U15)+1) | Z15: =IF(OR($S15="",$K15="",1-$K15=0),"",$S15/(1-$K15))
G16: =IF($E16="","",MIN(1,MAX(0,(LOG10($E16)-LOG10(Nmin))/(LOG10(Nmax)-LOG10(Nmin))))) | M16: =IF($L16="","",CHOOSE($L16,0.1,0.3,0.5,0.75,1)) | N16: =IF(OR($F16="",$H16="",$I16=""),"",$F16*$H16*$I16) | O16: =IF(OR($N16="",$J16=""),"",$N16*(1-$J16)) | P16: =IF($O16="","",IF($O16<0.05,"1 · Low",IF($O16<0.15,"2 · Moderate",IF($O16<0.35,"3 · High",IF($O16<0.6,"4 · Severe","5 · Critical"))))) | Q16: =IF(OR($N16="",$K16=""),"",$N16*(1-$K16)) | R16: =IF($Q16="","",IF($Q16<0.05,"1 · Low",IF($Q16<0.15,"2 · Moderate",IF($Q16<0.35,"3 · High",IF($Q16<0.6,"4 · Severe","5 · Critical"))))) | S16: =IF(OR($O16="",$Q16=""),"",($O16-$Q16)/$O16) | T16: =IF(OR($F16="",$M16="",$J16=""),"",$F16*$M16*(1-$J16)) | U16: =IF(OR($F16="",$M16="",$K16=""),"",$F16*$M16*(1-$K16)) | V16: =IF(OR($T16="",$E16=""),"",$T16/$E16*1000000) | W16: =IF($O16="","",COUNTIFS($P$5:$P$17,$P16,$T$5:$T$17,">"&$T16)+1) | X16: =IF(OR($U16="",$E16=""),"",$U16/$E16*1000000) | Y16: =IF(OR($Q16="",$R16=""),"",COUNTIFS($R$5:$R$17,$R16,$U$5:$U$17,">"&$U16)+1) | Z16: =IF(OR($S16="",$K16="",1-$K16=0),"",$S16/(1-$K16))
G17: =IF($E17="","",MIN(1,MAX(0,(LOG10($E17)-LOG10(Nmin))/(LOG10(Nmax)-LOG10(Nmin))))) | M17: =IF($L17="","",CHOOSE($L17,0.1,0.3,0.5,0.75,1)) | N17: =IF(OR($F17="",$H17="",$I17=""),"",$F17*$H17*$I17) | O17: =IF(OR($N17="",$J17=""),"",$N17*(1-$J17)) | P17: =IF($O17="","",IF($O17<0.05,"1 · Low",IF($O17<0.15,"2 · Moderate",IF($O17<0.35,"3 · High",IF($O17<0.6,"4 · Severe","5 · Critical"))))) | Q17: =IF(OR($N17="",$K17=""),"",$N17*(1-$K17)) | R17: =IF($Q17="","",IF($Q17<0.05,"1 · Low",IF($Q17<0.15,"2 · Moderate",IF($Q17<0.35,"3 · High",IF($Q17<0.6,"4 · Severe","5 · Critical"))))) | S17: =IF(OR($O17="",$Q17=""),"",($O17-$Q17)/$O17) | T17: =IF(OR($F17="",$M17="",$J17=""),"",$F17*$M17*(1-$J17)) | U17: =IF(OR($F17="",$M17="",$K17=""),"",$F17*$M17*(1-$K17)) | V17: =IF(OR($T17="",$E17=""),"",$T17/$E17*1000000) | W17: =IF($O17="","",COUNTIFS($P$5:$P$17,$P17,$T$5:$T$17,">"&$T17)+1) | X17: =IF(OR($U17="",$E17=""),"",$U17/$E17*1000000) | Y17: =IF(OR($Q17="",$R17=""),"",COUNTIFS($R$5:$R$17,$R17,$U$5:$U$17,">"&$U17)+1) | Z17: =IF(OR($S17="",$K17="",1-$K17=0),"",$S17/(1-$K17))
A19: Notes: Worked examples use each case's published rubric exposure (E used). E (log) shows the population-derived value for comparison — for Lagos this is ≈0.98 vs 0.65 used. Comparator rows carry illustrative inputs; R is recomputed uniformly as L·E·V·(1−ρ), correcting arithmetic in the source comparison table. Comparator ρ after values (Nairobi 0.65, Dar es Salaam 0.70, Lusaka 0.60) match the RMTI-Py cohort (Tables 4–6). C (1–5) is the analyst rubric score you enter (1 = Insignificant → 5 = Severe). C (0–1) is the auto-converted value the formula uses: 1→0.10, 2→0.30, 3→0.50, 4→0.75, 5→1.00 — do not edit column M. | NEW COLUMNS (X–Z): Per-capita after = EAL after ÷ N × 1 000 000 — equity lens post-investment. Priority after = rank by EAL after within the post-investment tier group (resets per tier; same method as Priority now). Investment Efficiency Index (IEI) = Δ risk ÷ (1 − ρ after) — measures how much risk reduction is achieved per unit of residual exposure retained. IEI > 1 means the intervention is highly leveraged; IEI near 0 means ρ after is high but risk barely moved.
A20: © 2025–2026 Cesar Marolla. The Risk Mechanism Theory Index (RMTI) was developed for ENVR E-241 Risk by Design. Licensed under the Apache License, Version 2.0 (see LICENSE and NOTICE in the repository). Copyright 2026 Cesar Marolla (ORCID 0000-0001-8498-7380). Provided "as is", without warranty.

Sheet Trajectory
A1: Trajectory — time-indexed V(t) and ρ(t) (experimental extension, not in the published RMTI papers)
A2: Warm cells with blue text are inputs; grey cells calculate. One row per annual review cycle, filled in order from t = 0; leave unused trailing rows blank. Both example cities are SYNTHETIC. Research prototype: not validated; every parameter below is an uncalibrated placeholder.
A4: Model parameters (shared by both blocks)
A5: v_lo — V at indicator = 0 | B5: 0.35 | C5: Placeholder anchor (copied from the HCC ALBI grade-1 anchor). Replace with a value justified for your hazard and portfolio.
A6: v_hi — V at indicator = y_max | B6: 0.85 | C6: Placeholder anchor (copied from the HCC ALBI grade-3 anchor).
A7: y_max | B7: 10 | C7: Top of the composite vulnerability-indicator scale (Table 9.4 RMTseen indicators scored 0–y_max, higher = more vulnerable). Placeholder 10.
A8: α — level gain | B8: 0.41 | C8: Steady-state Kalman gain for noise settings q_level 0.05, q_slope 0.01, r_obs 0.8 (RMTI-Py steady_state_gains). Uncalibrated.
A9: β — slope gain | B9: 0.09 | C9: Steady-state Kalman slope gain, same settings. Uncalibrated.
A10: κ·H — look-ahead (cycles) | B10: 1 | C10: Weight on the slope in V*(t). Uncalibrated; the synthetic comparison in the PDF used 2.0.
A11: λ — delivery → ρ | B11: 1 | C11: ρ(t) = ρ(t−1) + λ·ΔDelivery. Placeholder. Must be estimated from real programme-delivery data.
A12: ρ ceiling | B12: 0.95 | C12: Modeling ceiling (core rejects ρ ≥ 1).
A13: Filter on (1) / off (0) | B13: 1 | C13: 0 = use the observed indicator directly (memoryless). 1 = use filtered level + κ·H × slope.
A15: Synthetic example T-A — vulnerability indicator falling, programme delivery rising
A16: L — likelihood | B16: 0.3
A17: E — exposure | B17: 0.65
A18: C — consequence (1–5), shown for EAL only | B18: 3
A19: ρ at t = 0 | B19: 0.2
A21: Cycle t | B21: Indicator observed (0–y_max) | C21: Delivery (0–1) | D21: Indicator level (filtered) | E21: Indicator slope / cycle | F21: V*(t) | G21: ρ(t) | H21: R(t) | I21: Tier | J21: ΔR vs previous | K21: Posture
A22: 0 | B22: 2 | C22: 0.4 | D22: =IF(AND($B22="",$C22=""),"",$B22) -> 2 | E22: =IF(AND($B22="",$C22=""),"",0) -> 0 | F22: =IF(AND($B22="",$C22=""),"",$B$5+($B$6-$B$5)*MAX(0,MIN($B$7,IF($B$13=1,$D22+$B$10*$E22,IF($B22="",$D22,$B22))))/$B$7) -> 0.45 | G22: =IF(AND($B22="",$C22=""),"",$B$19) -> 0.2 | H22: =IF(AND($B22="",$C22=""),"",ROUND($B$16*$B$17*$F22*(1-$G22),12)) -> 0.0702 | I22: =IF(AND($B22="",$C22=""),"",INDEX(Reference!$B$10:$B$14,MATCH($H22,{0,0.05,0.15,0.35,0.6},1))) -> 2 · Moderate | J22: ="" | K22: =IF(AND($B22="",$C22=""),"",INDEX(Reference!$D$10:$D$14,MATCH($H22,{0,0.05,0.15,0.35,0.6},1))) -> Low-regret preventive measures
A23: 1 | B23: 1 | C23: 0.55 | D23: =IF(AND($B23="",$C23=""),"",IF($B23="",($D22+$E22),($D22+$E22)+$B$8*($B23-($D22+$E22)))) -> 1.59 | E23: =IF(AND($B23="",$C23=""),"",IF($B23="",$E22,$E22+$B$9*($B23-($D22+$E22)))) -> -0.09 | F23: =IF(AND($B23="",$C23=""),"",$B$5+($B$6-$B$5)*MAX(0,MIN($B$7,IF($B$13=1,$D23+$B$10*$E23,IF($B23="",$D23,$B23))))/$B$7) -> 0.425 | G23: =IF(AND($B23="",$C23=""),"",IF($C23="",$G22,MIN($B$12,MAX(0,$G22+$B$11*($C23-$C22))))) -> 0.35 | H23: =IF(AND($B23="",$C23=""),"",ROUND($B$16*$B$17*$F23*(1-$G23),12)) -> 0.05386875 | I23: =IF(AND($B23="",$C23=""),"",INDEX(Reference!$B$10:$B$14,MATCH($H23,{0,0.05,0.15,0.35,0.6},1))) -> 2 · Moderate | J23: =IF(AND($B23="",$C23=""),"",$H23-$H22) -> -0.01633125 | K23: =IF(AND($B23="",$C23=""),"",INDEX(Reference!$D$10:$D$14,MATCH($H23,{0,0.05,0.15,0.35,0.6},1))) -> Low-regret preventive measures
A24: 2 | B24: 1 | C24: 0.7 | D24: =IF(AND($B24="",$C24=""),"",IF($B24="",($D23+$E23),($D23+$E23)+$B$8*($B24-($D23+$E23)))) -> 1.295 | E24: =IF(AND($B24="",$C24=""),"",IF($B24="",$E23,$E23+$B$9*($B24-($D23+$E23)))) -> -0.135 | F24: =IF(AND($B24="",$C24=""),"",$B$5+($B$6-$B$5)*MAX(0,MIN($B$7,IF($B$13=1,$D24+$B$10*$E24,IF($B24="",$D24,$B24))))/$B$7) -> 0.408 | G24: =IF(AND($B24="",$C24=""),"",IF($C24="",$G23,MIN($B$12,MAX(0,$G23+$B$11*($C24-$C23))))) -> 0.5 | H24: =IF(AND($B24="",$C24=""),"",ROUND($B$16*$B$17*$F24*(1-$G24),12)) -> 0.03978 | I24: =IF(AND($B24="",$C24=""),"",INDEX(Reference!$B$10:$B$14,MATCH($H24,{0,0.05,0.15,0.35,0.6},1))) -> 1 · Low | J24: =IF(AND($B24="",$C24=""),"",$H24-$H23) -> -0.01408875 | K24: =IF(AND($B24="",$C24=""),"",INDEX(Reference!$D$10:$D$14,MATCH($H24,{0,0.05,0.15,0.35,0.6},1))) -> Monitor; maintain baseline
A25: 3 | B25: 0 | C25: 0.75 | D25: =IF(AND($B25="",$C25=""),"",IF($B25="",($D24+$E24),($D24+$E24)+$B$8*($B25-($D24+$E24)))) -> 0.6844 | E25: =IF(AND($B25="",$C25=""),"",IF($B25="",$E24,$E24+$B$9*($B25-($D24+$E24)))) -> -0.2394 | F25: =IF(AND($B25="",$C25=""),"",$B$5+($B$6-$B$5)*MAX(0,MIN($B$7,IF($B$13=1,$D25+$B$10*$E25,IF($B25="",$D25,$B25))))/$B$7) -> 0.37225 | G25: =IF(AND($B25="",$C25=""),"",IF($C25="",$G24,MIN($B$12,MAX(0,$G24+$B$11*($C25-$C24))))) -> 0.55 | H25: =IF(AND($B25="",$C25=""),"",ROUND($B$16*$B$17*$F25*(1-$G25),12)) -> 0.032664937 | I25: =IF(AND($B25="",$C25=""),"",INDEX(Reference!$B$10:$B$14,MATCH($H25,{0,0.05,0.15,0.35,0.6},1))) -> 1 · Low | J25: =IF(AND($B25="",$C25=""),"",$H25-$H24) -> -0.0071150625 | K25: =IF(AND($B25="",$C25=""),"",INDEX(Reference!$D$10:$D$14,MATCH($H25,{0,0.05,0.15,0.35,0.6},1))) -> Monitor; maintain baseline
A26: 4 | D26: =IF(AND($B26="",$C26=""),"",IF($B26="",($D25+$E25),($D25+$E25)+$B$8*($B26-($D25+$E25)))) | E26: =IF(AND($B26="",$C26=""),"",IF($B26="",$E25,$E25+$B$9*($B26-($D25+$E25)))) | F26: =IF(AND($B26="",$C26=""),"",$B$5+($B$6-$B$5)*MAX(0,MIN($B$7,IF($B$13=1,$D26+$B$10*$E26,IF($B26="",$D26,$B26))))/$B$7) | G26: =IF(AND($B26="",$C26=""),"",IF($C26="",$G25,MIN($B$12,MAX(0,$G25+$B$11*($C26-$C25))))) | H26: =IF(AND($B26="",$C26=""),"",ROUND($B$16*$B$17*$F26*(1-$G26),12)) | I26: =IF(AND($B26="",$C26=""),"",INDEX(Reference!$B$10:$B$14,MATCH($H26,{0,0.05,0.15,0.35,0.6},1))) | J26: =IF(AND($B26="",$C26=""),"",$H26-$H25) | K26: =IF(AND($B26="",$C26=""),"",INDEX(Reference!$D$10:$D$14,MATCH($H26,{0,0.05,0.15,0.35,0.6},1)))
A27: 5 | D27: =IF(AND($B27="",$C27=""),"",IF($B27="",($D26+$E26),($D26+$E26)+$B$8*($B27-($D26+$E26)))) | E27: =IF(AND($B27="",$C27=""),"",IF($B27="",$E26,$E26+$B$9*($B27-($D26+$E26)))) | F27: =IF(AND($B27="",$C27=""),"",$B$5+($B$6-$B$5)*MAX(0,MIN($B$7,IF($B$13=1,$D27+$B$10*$E27,IF($B27="",$D27,$B27))))/$B$7) | G27: =IF(AND($B27="",$C27=""),"",IF($C27="",$G26,MIN($B$12,MAX(0,$G26+$B$11*($C27-$C26))))) | H27: =IF(AND($B27="",$C27=""),"",ROUND($B$16*$B$17*$F27*(1-$G27),12)) | I27: =IF(AND($B27="",$C27=""),"",INDEX(Reference!$B$10:$B$14,MATCH($H27,{0,0.05,0.15,0.35,0.6},1))) | J27: =IF(AND($B27="",$C27=""),"",$H27-$H26) | K27: =IF(AND($B27="",$C27=""),"",INDEX(Reference!$D$10:$D$14,MATCH($H27,{0,0.05,0.15,0.35,0.6},1)))
A28: 6 | D28: =IF(AND($B28="",$C28=""),"",IF($B28="",($D27+$E27),($D27+$E27)+$B$8*($B28-($D27+$E27)))) | E28: =IF(AND($B28="",$C28=""),"",IF($B28="",$E27,$E27+$B$9*($B28-($D27+$E27)))) | F28: =IF(AND($B28="",$C28=""),"",$B$5+($B$6-$B$5)*MAX(0,MIN($B$7,IF($B$13=1,$D28+$B$10*$E28,IF($B28="",$D28,$B28))))/$B$7) | G28: =IF(AND($B28="",$C28=""),"",IF($C28="",$G27,MIN($B$12,MAX(0,$G27+$B$11*($C28-$C27))))) | H28: =IF(AND($B28="",$C28=""),"",ROUND($B$16*$B$17*$F28*(1-$G28),12)) | I28: =IF(AND($B28="",$C28=""),"",INDEX(Reference!$B$10:$B$14,MATCH($H28,{0,0.05,0.15,0.35,0.6},1))) | J28: =IF(AND($B28="",$C28=""),"",$H28-$H27) | K28: =IF(AND($B28="",$C28=""),"",INDEX(Reference!$D$10:$D$14,MATCH($H28,{0,0.05,0.15,0.35,0.6},1)))
A29: 7 | D29: =IF(AND($B29="",$C29=""),"",IF($B29="",($D28+$E28),($D28+$E28)+$B$8*($B29-($D28+$E28)))) | E29: =IF(AND($B29="",$C29=""),"",IF($B29="",$E28,$E28+$B$9*($B29-($D28+$E28)))) | F29: =IF(AND($B29="",$C29=""),"",$B$5+($B$6-$B$5)*MAX(0,MIN($B$7,IF($B$13=1,$D29+$B$10*$E29,IF($B29="",$D29,$B29))))/$B$7) | G29: =IF(AND($B29="",$C29=""),"",IF($C29="",$G28,MIN($B$12,MAX(0,$G28+$B$11*($C29-$C28))))) | H29: =IF(AND($B29="",$C29=""),"",ROUND($B$16*$B$17*$F29*(1-$G29),12)) | I29: =IF(AND($B29="",$C29=""),"",INDEX(Reference!$B$10:$B$14,MATCH($H29,{0,0.05,0.15,0.35,0.6},1))) | J29: =IF(AND($B29="",$C29=""),"",$H29-$H28) | K29: =IF(AND($B29="",$C29=""),"",INDEX(Reference!$D$10:$D$14,MATCH($H29,{0,0.05,0.15,0.35,0.6},1)))
A31: Synthetic example T-B — vulnerability indicator rising, delivery flat
A32: L — likelihood | B32: 0.3
A33: E — exposure | B33: 0.65
A34: C — consequence (1–5), shown for EAL only | B34: 3
A35: ρ at t = 0 | B35: 0.2
A37: Cycle t | B37: Indicator observed (0–y_max) | C37: Delivery (0–1) | D37: Indicator level (filtered) | E37: Indicator slope / cycle | F37: V*(t) | G37: ρ(t) | H37: R(t) | I37: Tier | J37: ΔR vs previous | K37: Posture
A38: 0 | B38: 2 | C38: 0.4 | D38: =IF(AND($B38="",$C38=""),"",$B38) -> 2 | E38: =IF(AND($B38="",$C38=""),"",0) -> 0 | F38: =IF(AND($B38="",$C38=""),"",$B$5+($B$6-$B$5)*MAX(0,MIN($B$7,IF($B$13=1,$D38+$B$10*$E38,IF($B38="",$D38,$B38))))/$B$7) -> 0.45 | G38: =IF(AND($B38="",$C38=""),"",$B$35) -> 0.2 | H38: =IF(AND($B38="",$C38=""),"",ROUND($B$32*$B$33*$F38*(1-$G38),12)) -> 0.0702 | I38: =IF(AND($B38="",$C38=""),"",INDEX(Reference!$B$10:$B$14,MATCH($H38,{0,0.05,0.15,0.35,0.6},1))) -> 2 · Moderate | J38: ="" | K38: =IF(AND($B38="",$C38=""),"",INDEX(Reference!$D$10:$D$14,MATCH($H38,{0,0.05,0.15,0.35,0.6},1))) -> Low-regret preventive measures
A39: 1 | B39: 3 | C39: 0.4 | D39: =IF(AND($B39="",$C39=""),"",IF($B39="",($D38+$E38),($D38+$E38)+$B$8*($B39-($D38+$E38)))) -> 2.41 | E39: =IF(AND($B39="",$C39=""),"",IF($B39="",$E38,$E38+$B$9*($B39-($D38+$E38)))) -> 0.09 | F39: =IF(AND($B39="",$C39=""),"",$B$5+($B$6-$B$5)*MAX(0,MIN($B$7,IF($B$13=1,$D39+$B$10*$E39,IF($B39="",$D39,$B39))))/$B$7) -> 0.475 | G39: =IF(AND($B39="",$C39=""),"",IF($C39="",$G38,MIN($B$12,MAX(0,$G38+$B$11*($C39-$C38))))) -> 0.2 | H39: =IF(AND($B39="",$C39=""),"",ROUND($B$32*$B$33*$F39*(1-$G39),12)) -> 0.0741 | I39: =IF(AND($B39="",$C39=""),"",INDEX(Reference!$B$10:$B$14,MATCH($H39,{0,0.05,0.15,0.35,0.6},1))) -> 2 · Moderate | J39: =IF(AND($B39="",$C39=""),"",$H39-$H38) -> 0.0039 | K39: =IF(AND($B39="",$C39=""),"",INDEX(Reference!$D$10:$D$14,MATCH($H39,{0,0.05,0.15,0.35,0.6},1))) -> Low-regret preventive measures
A40: 2 | B40: 4 | C40: 0.35 | D40: =IF(AND($B40="",$C40=""),"",IF($B40="",($D39+$E39),($D39+$E39)+$B$8*($B40-($D39+$E39)))) -> 3.115 | E40: =IF(AND($B40="",$C40=""),"",IF($B40="",$E39,$E39+$B$9*($B40-($D39+$E39)))) -> 0.225 | F40: =IF(AND($B40="",$C40=""),"",$B$5+($B$6-$B$5)*MAX(0,MIN($B$7,IF($B$13=1,$D40+$B$10*$E40,IF($B40="",$D40,$B40))))/$B$7) -> 0.517 | G40: =IF(AND($B40="",$C40=""),"",IF($C40="",$G39,MIN($B$12,MAX(0,$G39+$B$11*($C40-$C39))))) -> 0.15 | H40: =IF(AND($B40="",$C40=""),"",ROUND($B$32*$B$33*$F40*(1-$G40),12)) -> 0.08569275 | I40: =IF(AND($B40="",$C40=""),"",INDEX(Reference!$B$10:$B$14,MATCH($H40,{0,0.05,0.15,0.35,0.6},1))) -> 2 · Moderate | J40: =IF(AND($B40="",$C40=""),"",$H40-$H39) -> 0.01159275 | K40: =IF(AND($B40="",$C40=""),"",INDEX(Reference!$D$10:$D$14,MATCH($H40,{0,0.05,0.15,0.35,0.6},1))) -> Low-regret preventive measures
A41: 3 | B41: 5 | C41: 0.35 | D41: =IF(AND($B41="",$C41=""),"",IF($B41="",($D40+$E40),($D40+$E40)+$B$8*($B41-($D40+$E40)))) -> 4.0206 | E41: =IF(AND($B41="",$C41=""),"",IF($B41="",$E40,$E40+$B$9*($B41-($D40+$E40)))) -> 0.3744 | F41: =IF(AND($B41="",$C41=""),"",$B$5+($B$6-$B$5)*MAX(0,MIN($B$7,IF($B$13=1,$D41+$B$10*$E41,IF($B41="",$D41,$B41))))/$B$7) -> 0.56975 | G41: =IF(AND($B41="",$C41=""),"",IF($C41="",$G40,MIN($B$12,MAX(0,$G40+$B$11*($C41-$C40))))) -> 0.15 | H41: =IF(AND($B41="",$C41=""),"",ROUND($B$32*$B$33*$F41*(1-$G41),12)) -> 0.094436063 | I41: =IF(AND($B41="",$C41=""),"",INDEX(Reference!$B$10:$B$14,MATCH($H41,{0,0.05,0.15,0.35,0.6},1))) -> 2 · Moderate | J41: =IF(AND($B41="",$C41=""),"",$H41-$H40) -> 0.0087433125 | K41: =IF(AND($B41="",$C41=""),"",INDEX(Reference!$D$10:$D$14,MATCH($H41,{0,0.05,0.15,0.35,0.6},1))) -> Low-regret preventive measures
A42: 4 | D42: =IF(AND($B42="",$C42=""),"",IF($B42="",($D41+$E41),($D41+$E41)+$B$8*($B42-($D41+$E41)))) | E42: =IF(AND($B42="",$C42=""),"",IF($B42="",$E41,$E41+$B$9*($B42-($D41+$E41)))) | F42: =IF(AND($B42="",$C42=""),"",$B$5+($B$6-$B$5)*MAX(0,MIN($B$7,IF($B$13=1,$D42+$B$10*$E42,IF($B42="",$D42,$B42))))/$B$7) | G42: =IF(AND($B42="",$C42=""),"",IF($C42="",$G41,MIN($B$12,MAX(0,$G41+$B$11*($C42-$C41))))) | H42: =IF(AND($B42="",$C42=""),"",ROUND($B$32*$B$33*$F42*(1-$G42),12)) | I42: =IF(AND($B42="",$C42=""),"",INDEX(Reference!$B$10:$B$14,MATCH($H42,{0,0.05,0.15,0.35,0.6},1))) | J42: =IF(AND($B42="",$C42=""),"",$H42-$H41) | K42: =IF(AND($B42="",$C42=""),"",INDEX(Reference!$D$10:$D$14,MATCH($H42,{0,0.05,0.15,0.35,0.6},1)))
A43: 5 | D43: =IF(AND($B43="",$C43=""),"",IF($B43="",($D42+$E42),($D42+$E42)+$B$8*($B43-($D42+$E42)))) | E43: =IF(AND($B43="",$C43=""),"",IF($B43="",$E42,$E42+$B$9*($B43-($D42+$E42)))) | F43: =IF(AND($B43="",$C43=""),"",$B$5+($B$6-$B$5)*MAX(0,MIN($B$7,IF($B$13=1,$D43+$B$10*$E43,IF($B43="",$D43,$B43))))/$B$7) | G43: =IF(AND($B43="",$C43=""),"",IF($C43="",$G42,MIN($B$12,MAX(0,$G42+$B$11*($C43-$C42))))) | H43: =IF(AND($B43="",$C43=""),"",ROUND($B$32*$B$33*$F43*(1-$G43),12)) | I43: =IF(AND($B43="",$C43=""),"",INDEX(Reference!$B$10:$B$14,MATCH($H43,{0,0.05,0.15,0.35,0.6},1))) | J43: =IF(AND($B43="",$C43=""),"",$H43-$H42) | K43: =IF(AND($B43="",$C43=""),"",INDEX(Reference!$D$10:$D$14,MATCH($H43,{0,0.05,0.15,0.35,0.6},1)))
A44: 6 | D44: =IF(AND($B44="",$C44=""),"",IF($B44="",($D43+$E43),($D43+$E43)+$B$8*($B44-($D43+$E43)))) | E44: =IF(AND($B44="",$C44=""),"",IF($B44="",$E43,$E43+$B$9*($B44-($D43+$E43)))) | F44: =IF(AND($B44="",$C44=""),"",$B$5+($B$6-$B$5)*MAX(0,MIN($B$7,IF($B$13=1,$D44+$B$10*$E44,IF($B44="",$D44,$B44))))/$B$7) | G44: =IF(AND($B44="",$C44=""),"",IF($C44="",$G43,MIN($B$12,MAX(0,$G43+$B$11*($C44-$C43))))) | H44: =IF(AND($B44="",$C44=""),"",ROUND($B$32*$B$33*$F44*(1-$G44),12)) | I44: =IF(AND($B44="",$C44=""),"",INDEX(Reference!$B$10:$B$14,MATCH($H44,{0,0.05,0.15,0.35,0.6},1))) | J44: =IF(AND($B44="",$C44=""),"",$H44-$H43) | K44: =IF(AND($B44="",$C44=""),"",INDEX(Reference!$D$10:$D$14,MATCH($H44,{0,0.05,0.15,0.35,0.6},1)))
A45: 7 | D45: =IF(AND($B45="",$C45=""),"",IF($B45="",($D44+$E44),($D44+$E44)+$B$8*($B45-($D44+$E44)))) | E45: =IF(AND($B45="",$C45=""),"",IF($B45="",$E44,$E44+$B$9*($B45-($D44+$E44)))) | F45: =IF(AND($B45="",$C45=""),"",$B$5+($B$6-$B$5)*MAX(0,MIN($B$7,IF($B$13=1,$D45+$B$10*$E45,IF($B45="",$D45,$B45))))/$B$7) | G45: =IF(AND($B45="",$C45=""),"",IF($C45="",$G44,MIN($B$12,MAX(0,$G44+$B$11*($C45-$C44))))) | H45: =IF(AND($B45="",$C45=""),"",ROUND($B$32*$B$33*$F45*(1-$G45),12)) | I45: =IF(AND($B45="",$C45=""),"",INDEX(Reference!$B$10:$B$14,MATCH($H45,{0,0.05,0.15,0.35,0.6},1))) | J45: =IF(AND($B45="",$C45=""),"",$H45-$H44) | K45: =IF(AND($B45="",$C45=""),"",INDEX(Reference!$D$10:$D$14,MATCH($H45,{0,0.05,0.15,0.35,0.6},1)))
...
